Workbook

Sheet Claude Log
A1: Turn # | B1: Date | C1: User Request | D1: Action Taken | E1: Details | F1: Outcome
A2: 1 | B2: 46254 | C2: Confirm whether ontology definitions for the 5 AHUs (SSC_AHUB0001-0005) match in count, and identify discrepancies; put results on a separate sheet. | D2: Created 'AHU_Comparison' sheet with per-unit triple counts, a discrepancy table, and a full 135-relation matrix. | E2: Normalised each triple in SSC_Ontology_Ver0.5!A128:D773 by replacing the AHU id with {N}, then counted each pattern per unit with COUNTIFS+SUBSTITUTE formulas (live-linked to source). Status flags via MIN/MAX. Conditional formatting highlights non-OK rows. | F2: Counts do NOT match: 129/130/128/132/127 rows. 12 of 135 relation patterns differ - 3 location rows (expected), missing SAP_Setpoint on 0003/0005, missing RF_AutoMan_Status on 0004, duplicated SA_P-Static ref on 0002/0003/0004, extra RA_P-Static_01/_02 on 0004.
A3: 2 | B3: 46254 | C3: Disregard the rec:locatedIn discrepancies. | D3: Removed the 3 location rows from the discrepancy table and flagged them as excluded in the full matrix. | E3: Deleted rows 20:22 (sections below shifted up: matrix header now row 22, data 23:157). Status formula now returns 'Excluded - location varies by unit' when column B = rec:locatedIn; conditional highlight skips excluded rows. Header note in A2/A9 updated. | F3: Discrepancy count now 9 real issues across 135 relations (123 OK, 8 not-on-all-units, 1 duplicated, 3 excluded locations).
A4: 3 | B4: 46254 | C4: Run the same consistency comparison for the newly selected range (A815:E1346) on its own sheet. | D4: Created 'CCU_Comparison' sheet comparing the 14 CCU/CRAC units in SSC_Ontology_Ver0.5!A815:E1346. | E4: Unit ids are non-sequential (CCU3F0301, CCUB0001A/B, ... CCUB0008), so ids were detected by regex rather than assumed. Same method as AHU sheet: normalise unit id to {U}, count each pattern per unit with COUNTIFS+SUBSTITUTE. Also compared the two type columns (B, E) which the AHU range did not have. | F4: Counts MATCH: all 14 units have 38 rows; 37 of 40 relation patterns present exactly once on every unit; 3 rec:locatedIn patterns excluded per user. Type columns consistent. No missing or duplicated rows.
A5: 4 | B5: 46254 | C5: For the CCUs not located in B1_023_Q_TEL or B1_017_MDF-2, do they have a unique rec:locatedIn triple? | D5: Audited rec:locatedIn per CCU and added a 'Location breakdown' table to CCU_Comparison (rows 59-76). | E5: Per-unit triple count via COUNTIFS; room resolved with TEXTJOIN+IF array formula against SSC_Ontology_Ver0.5!A815:D1346; room occupancy via COUNTIFS on predicate+object. Kept as live formulas. | F5: Answer: yes, each of the 14 CCUs has exactly one rec:locatedIn triple - none missing or duplicated. But the rooms are shared, not unique: the 6 units outside Q_TEL/MDF-2 all sit in B1_038_SER-2.
A6: 5 | B6: 46254 | C6: Run the same consistency exercise for the chilled water pumps in SSC_Ontology_Ver0.5!A1347:E1422. | D6: Created 'CHWP_Comparison' sheet comparing the 4 chilled water booster pumps (SSC_CHW_CHWP01-04). | E6: Same method: normalise pump id to {P}, count each of the 19 relation patterns per pump with COUNTIFS+SUBSTITUTE against A1347:D1422; compared subject/object type columns; status flag via MIN/MAX. | F6: Fully consistent: 19 rows per pump, 19/19 patterns present exactly once on every pump, types identical, all 4 in the same room (B1_014_VENT_PLANT) so no location variance either. Flagged one non-error observation: pumps have Speed_Command/Speed_Fbk but no run status or auto-manual point on any of the 4.
A7: 6 | B7: 46254 | C7: Run the same consistency exercise for the heat exchangers in SSC_Ontology_Ver0.5!A1423:E1572. | D7: Created 'HE_Comparison' sheet comparing the 5 chilled water heat exchangers (SSC_CHW_HE01-HE05). | E7: Same method: normalise HE id to {H}, count all 32 relation patterns per unit with COUNTIFS+SUBSTITUTE against A1423:D1572; compared subject/object type columns. Sheet has count summary (rows 5-7), findings (10-14), discrepancy table (17-27) and full matrix (29-61). | F7: Counts DO NOT match: HE01-04 = 32 rows, HE05 = 22 (10 short). All 10 missing rows are on HE05's Supply_Valve (Auto_Command, Manual_Auto_Status, Close_Command, Open_Command, Status + their 5 external references); only Temperature_Sensor remains. Everything else identical, all 5 in same room. Flagged two uniform modelling issues: Open/Close_Command para types look swapped, and Return_Valve has both _Open_Close_Status and _Status with the same class.
A8: 7 | B8: 46254 | C8: Challenged whether the whole worksheet was checked for heat exchanger rows, not just the selected range. | D8: Scanned the entire used range of SSC_Ontology_Ver0.5 (5,120 rows x 27 cols) for heat exchanger references. | E8: Matched on HE0x, HEX, HX, PHE, 'Plate Heat', 'Exchanger' and 'heat exchanger' across all columns of every row. 150 hits found, all within rows 1423-1572. The 25 'Exchanger' hits are the brick:Heat_Exchanger class cells (5 units x 5 rows) inside that same block. | F8: Confirmed: no heat exchanger data exists outside A1423:E1572, so HE_Comparison covers the complete set. Also inspected the user's newly inserted rows 1671-1680 - these are DX unit rec:feeds triples, unrelated to HEs.
A9: 8 | B9: 46254 | C9: Run the same consistency exercise for the DX units in SSC_Ontology_Ver0.5!A1573:E1680. | D9: Created 'DX_Comparison' sheet comparing the 10 DX units (SSC_DXB0001-DXB0010), after first sweeping the whole sheet for stray DX rows. | E9: Whole-sheet scan found one DX row outside the range - row 4988, 'para:DXUnit owl:Class rdfs:subClassOf brick:HVAC_Equipment' - which is a class definition, not instance data, so it was excluded. Same method as prior sheets: normalise id to {D}, COUNTIFS+SUBSTITUTE per unit over A1573:D1680. Both rec:locatedIn and rec:feeds excluded from the pass/fail flag since both legitimately vary by room. Added a location/feeds breakdown table. | F9: Counts DO NOT match: DXB0001-0006 = 10 rows, DXB0007-0010 = 12. Whole difference is the Humidity_Sensor point + its external reference, present only on the 4 units in FM STORAGE rooms - likely intentional, flagged for confirmation. Matrix: 8 OK, 2 not-on-all-units, 10 excluded. Also flagged that all 10 units have rec:feeds pointing at the same room as rec:locatedIn.
A10: 9 | B10: 46254 | C10: Run the same consistency exercise for the FCUs in SSC_Ontology_Ver0.5!A1681:E2208. | D10: Created 'FCU_Comparison' sheet comparing the 11 FCUs (SSC_FCU0001-FCU0011), after sweeping the whole sheet for stray FCU rows. | E10: Whole-sheet scan found zero FCU rows outside A1681:E2208, so the set is complete. Same method: normalise id to {F}, COUNTIFS+SUBSTITUTE per unit; rec:locatedIn and rec:feeds excluded from the pass/fail flag. Sheet: counts (5-7), findings (10-14), 64-pattern matrix (17-81), location/feeds breakdown (83-95). | F10: Fully consistent: 48 rows on every FCU; 46 structural patterns present exactly once on all 11; 18 excluded location/feeds patterns covering 9 distinct rooms, one locatedIn and one feeds per unit. No type inconsistencies. Flagged again that rec:feeds points at the same room as rec:locatedIn on all 11 units.
A11: 10 | B11: 46254 | C11: Run the same consistency exercise for the selected range A2209:E2238. | D11: Found the range held only one unit, widened scope to all 7 brick:Exhaust_Fan entities (rows 2209-2492) and created 'EF_Comparison'. | E11: Selected range contained only GEFB0001, so a whole-sheet scan identified every entity typed brick:Exhaust_Fan: GEFB0001, KEF0103, KEF0303, TEF0101/0102/0301/0302. Rows 2343-2372 (Levels, MV Generator) fall inside the span and were excluded. Matrix uses Presence and Duplication columns instead of a single status because duplication and absence are separate problems here. Distinct-relation row is a SUMPRODUCT over the matrix. | F11: Counts DO NOT match: GEF + 4 TEFs = 30 rows, KEF0103/KEF0303 = 52. KEFs are duplicated end to end (26 distinct relations x2). Three point sets in use - only 24 of 36 patterns shared by all 7. Type inconsistency: Motor_Running_Status is brick:On_Off_Status on GEF/KEFs but brick:Fan_Status on TEFs. Major flag: all 7 fans are locatedIn and feed the same room, entity:Level7_Office0367 - likely placeholder data.
A12: 11 | B12: 46254 | C12: Run the same exercise for the generator (selected range A2347:E2371). | D12: Created 'GEN_Check' sheet - an internal integrity audit rather than a cross-unit comparison, because only one generator exists. | E12: Whole-sheet scan for GEN/Generator returned 71 hits but nearly all were false positives (GENERAL OFFICE rooms, 'General Fault/Alarm' labels, the B1_012_GENERATOR room definition, the para:Generator class row at 4992). Only one generator instance: SSC_MV_Generator. Since there is no peer, the sheet tests each point for exactly one hasPoint declaration and one external reference, and locates every generator triple with an AGGREGATE-based row finder (SUMPRODUCT version returned #N/A because the source columns contain error cells). | F12: 26 generator triples: 25 in the selected block, 1 detached. All 10 points declared once and referenced once - internally clean. Flagged: rec:locatedIn sits alone at row 5013 instead of inside the block; 'Generator_Generator_Running_Status' name stutter; inconsistent _Reading suffixes; no rec:feeds triple.
A13: 12 | B13: 46254 | C13: Run the same consistency exercise for the VAVs (ranges A2493:E4976 and A5014:E5120). | D13: Created 'VAV_Comparison' covering all 108 VAV units, and found 19 corrupted rows that a row-count check alone would miss. | E13: 108 units x 24 rows is too wide for a per-unit column grid, so the sheet tests each structural relation for an expected count of 108 using COUNTIFS with wildcard entity patterns, plus a 108-row per-unit count table. A first pass normalising on exact object values produced 191 meaningless patterns because rated flowrates/rooms are per-unit literals; re-normalised so unit-specific values collapse to one token, giving 27 real structural patterns. Whole-sheet scan confirmed no VAV rows outside the two selected ranges. | F13: Row counts: 107 units have 24 rows, VAV0063 has 23 (missing its rec:feeds triple). Content check found 19 rows where the object column holds a value instead of an entity: VAV0102 (9 rows), VAV0103 (8), VAV0101 (1) all contain the number 130 in place of point/part names, and VAV0063 row 3931 holds #N/A in its locatedIn object. VAV0102 and VAV0103 still total 24 rows each, so only the content check catches them.
... A16: 15 | B16: 46254 | C16: Pointed out that ref:hasExternalReference rows are also corrupted (object = 130 instead of <blanknode>), not just the 18 structural rows, and asked for these to be shown in the VAV sheet. | D16: Rescanned every VAV row for non-text objects, expanded section 4 from 19 to 37 rows, added a reference-object check to section 3, and highlighted the 18 additional source rows yellow. | E16: My earlier scan only tested hasPart/hasPoint rows - a scoping error on my part. Full rescan of all 2,591 VAV rows found 253 non-text objects, of which 216 are legitimate (para:ratedReheatCapacity and para:ratedSupplyAirFlowrate carry numeric values by design) and 1 is VAV0063's accepted #N/A. Real corruption = 36 rows: 18 structural + 18 reference. Inserted 18 rows at 68 to grow the table, so section 5 moved from row 70 to 88; dependent formulas adjusted automatically and the B10 metric range was repointed manually to D50:D85. | F16: 36 corrupted rows confirmed: VAV0101 = 10 (1 structural + 9 refs), VAV0102 = 18 (9 + 9), VAV0103 = 8 (structural only, refs intact). All 36 source rows verified yellow. New section 3 check row reports 'CORRUPT - 18 rows' for reference objects.

Sheet SSC_Ontology_Ver0.5
A1: Subject | B1: subjectType | C1: predicate | D1: object | E1: objectType | F1: subject_prop_name | G1: subject_prop_val | H1: object_prop_name | I1: object_prop_val | J1: subject_prop_name | K1: subject_prop_val | L1: object_prop_name | M1: object_prop_val | N1: subject_prop_name | O1: subject_prop_val | P1: object_prop_name | Q1: object_prop_val | R1: subject_prop_name | S1: subject_prop_val | T1: object_prop_name | U1: object_prop_val | V1: subject_prop_name | W1: subject_prop_val | X1: object_prop_name | Y1: object_prop_val | Z1: subject_prop_name | AA1: subject_prop_val
A2: entity:CHWS-MAIN-LOOP | B2: para:Chilled_Water_Loop_Network | C2: ref:hasExternalReference | D2: <blanknode> | E2: ref:IFCReference | L2: ref:ifcName | M2: CHWS-MAIN-LOOP
A3: entity:CHWS-MAIN-LOOP | B3: para:Chilled_Water_Loop_Network | C3: rec:locatedIn | D3: entity:SSC | E3: rec:Building | N3: brick:aliasOf | O3: CHWS-MAIN-LOOP
A4: entity:CHW-System | B4: brick:Chilled_Water_System | C4: brick:isPartOf | D4: entity:HVAC | E4: brick:HVAC_System | F4: rdfs:label_en | G4: Chilled Water System
A5: entity:Electrical_System | B5: brick:System | C5: brick:isPartOf | D5: entity:QF | E5: rec:Site | F5: rdfs:label_en | G5: Electrical System
A6: entity:HVAC | B6: brick:HVAC_System | C6: brick:isPartOf | D6: entity:QF | E6: rec:Site | F6: rdfs:label_en | G6: HVAC System
A7: entity:SSC | B7: rec:Building | C7: rec:isPartOf | D7: entity:QF | E7: rec:Site | F7: rdfs:label_en | G7: SSC Building | H7: rdfs:label_en | I7: Qatar Foundation
A8: entity:SSC_01_001_CORRIDOR | B8: rec:Room | C8: rec:isPartOf | D8: entity:SSC_Level-01 | E8: rec:Level | F8: rdfs:label_en | G8: 1.001 CORRIDOR
A9: entity:SSC_01_002_SHELL_SPACE | B9: rec:Room | C9: rec:isPartOf | D9: entity:SSC_Level-01 | E9: rec:Level | F9: rdfs:label_en | G9: 1.002 SHELL SPACE
A10: entity:SSC_01_003_OPEN_SPACE | B10: rec:Room | C10: rec:isPartOf | D10: entity:SSC_Level-01 | E10: rec:Level | F10: rdfs:label_en | G10: 1.003 OPEN SPACE
A11: entity:SSC_01_004_CORRIDOR | B11: rec:Room | C11: rec:isPartOf | D11: entity:SSC_Level-01 | E11: rec:Level | F11: rdfs:label_en | G11: 1.004 CORRIDOR
A12: entity:SSC_01_005_KITCHEN | B12: rec:Room | C12: rec:isPartOf | D12: entity:SSC_Level-01 | E12: rec:Level | F12: rdfs:label_en | G12: 1.005 KITCHEN
A13: entity:SSC_01_006_MALE_TOILET | B13: rec:Room | C13: rec:isPartOf | D13: entity:SSC_Level-01 | E13: rec:Level | F13: rdfs:label_en | G13: 1.006 MALE TOILET
A14: entity:SSC_01_007_FEMALE_TOILET | B14: rec:Room | C14: rec:isPartOf | D14: entity:SSC_Level-01 | E14: rec:Level | F14: rdfs:label_en | G14: 1.007 FEMALE TOILET
A15: entity:SSC_01_008_AV_ROOM | B15: rec:Room | C15: rec:isPartOf | D15: entity:SSC_Level-01 | E15: rec:Level | F15: rdfs:label_en | G15: 1.008 A / V ROOM
A16: entity:SSC_01_009_AUDITORIUM | B16: rec:Room | C16: rec:isPartOf | D16: entity:SSC_Level-01 | E16: rec:Level | F16: rdfs:label_en | G16: 1.009 AUDITORIUM MEETING ROOM
A17: entity:SSC_01_010_CORRIDOR | B17: rec:Room | C17: rec:isPartOf | D17: entity:SSC_Level-01 | E17: rec:Level | F17: rdfs:label_en | G17: 1.01 CORRIDOR
A18: entity:SSC_01_011_AIR_LOCK | B18: rec:Room | C18: rec:isPartOf | D18: entity:SSC_Level-01 | E18: rec:Level | F18: rdfs:label_en | G18: 1.011 AIR LOCK
A19: entity:SSC_01_012_STORAGE | B19: rec:Room | C19: rec:isPartOf | D19: entity:SSC_Level-01 | E19: rec:Level | F19: rdfs:label_en | G19: 1.012 STORAGE
... A127: entity:SSC_03_ST-2_STAIR-2 | B127: rec:Room | C127: rec:isPartOf | D127: entity:SSC_Level-03 | E127: rec:Level | F127: rdfs:label_en | G127: 03.ST-2 STAIR-2
A128: entity:SSC_AHUB0001 | B128: brick:Air_Handling_Unit | C128: brick:hasPart | D128: entity:SSC_AHUB0001_CHW-Coil | E128: brick:Chilled_Water_Coil | H128: rdfs:label_en | I128: Chilled Water Coil
A129: entity:SSC_AHUB0001 | B129: brick:Air_Handling_Unit | C129: brick:hasPart | D129: entity:SSC_AHUB0001_Filter | E129: brick:Filter | H129: rdfs:label_en | I129: Pre Filter and Bag Filter
A130: entity:SSC_AHUB0001 | B130: brick:Air_Handling_Unit | C130: brick:hasPart | D130: entity:SSC_AHUB0001_OAD | E130: brick:Outside_Damper | H130: rdfs:label_en | I130: Outside Air Damper
A131: entity:SSC_AHUB0001 | B131: brick:Air_Handling_Unit | C131: brick:hasPart | D131: entity:SSC_AHUB0001_RAD | E131: brick:Return_Damper | H131: rdfs:label_en | I131: Return Air Damper
A132: entity:SSC_AHUB0001 | B132: brick:Air_Handling_Unit | C132: brick:hasPart | D132: entity:SSC_AHUB0001_MAD | E132: brick:Mixed_Damper | H132: rdfs:label_en | I132: Mixed Air Damper
A133: entity:SSC_AHUB0001 | B133: brick:Air_Handling_Unit | C133: brick:hasPart | D133: entity:SSC_AHUB0001_EAD | E133: brick:Exhaust_Damper | H133: rdfs:label_en | I133: Exhaust Air Damper
A134: entity:SSC_AHUB0001 | B134: brick:Air_Handling_Unit | C134: brick:hasPart | D134: entity:SSC_AHUB0001_RF | E134: brick:Return_Fan | H134: rdfs:label_en | I134: Return Fan
A135: entity:SSC_AHUB0001 | B135: brick:Air_Handling_Unit | C135: brick:hasPart | D135: entity:SSC_AHUB0001_SF | E135: brick:Supply_Fan | H135: rdfs:label_en | I135: Supply Fan
A136: entity:SSC_AHUB0001 | B136: brick:Air_Handling_Unit | C136: brick:hasPart | D136: entity:SSC_AHUB0001_Heater | E136: brick:Heater | H136: rdfs:label_en | I136: Heater
A137: entity:SSC_AHUB0001 | B137: brick:Air_Handling_Unit | C137: brick:hasPoint | D137: entity:SSC_AHUB0001_OA_RH | E137: brick:Outside_Air_Humidity_Sensor | H137: rdfs:label_en | I137: Fresh Air Humidity | L137: brick:hasUnit | M137: unit:PERCENT_RH
A138: entity:SSC_AHUB0001 | B138: brick:Air_Handling_Unit | C138: brick:hasPoint | D138: entity:SSC_AHUB0001_OA_Temperature | E138: brick:Outside_Air_Temperature_Sensor | H138: rdfs:label_en | I138: Fresh Air Temperature | L138: brick:hasUnit | M138: unit:DEG_C
A139: entity:SSC_AHUB0001 | B139: brick:Air_Handling_Unit | C139: brick:hasPoint | D139: entity:SSC_AHUB0001_RA_RH | E139: brick:Return_Air_Humidity_Sensor | H139: rdfs:label_en | I139: Return Air Humidity | L139: brick:hasUnit | M139: unit:PERCENT_RH
A140: entity:SSC_AHUB0001 | B140: brick:Air_Handling_Unit | C140: brick:hasPoint | D140: entity:SSC_AHUB0001_RA_Temperature | E140: brick:Return_Air_Temperature_Sensor | H140: rdfs:label_en | I140: Return Air Temperature | L140: brick:hasUnit | M140: unit:DEG_C
A141: entity:SSC_AHUB0001 | B141: brick:Air_Handling_Unit | C141: brick:hasPoint | D141: entity:SSC_AHUB0001_RA_Flow | E141: brick:Return_Air_Flow_Sensor | H141: rdfs:label_en | I141: Return Air Flow | L141: brick:hasUnit | M141: unit:L-PER-SEC
A142: entity:SSC_AHUB0001 | B142: brick:Air_Handling_Unit | C142: brick:hasPoint | D142: entity:SSC_AHUB0001_MA_Temperature | E142: brick:Mixed_Air_Temperature_Sensor | H142: rdfs:label_en | I142: Mixed Air Temperature | L142: brick:hasUnit | M142: unit:DEG_C
A143: entity:SSC_AHUB0001 | B143: brick:Air_Handling_Unit | C143: brick:hasPoint | D143: entity:SSC_AHUB0001_SA_Flow | E143: brick:Supply_Air_Flow_Sensor | H143: rdfs:label_en | I143: Supply Air Flow | L143: brick:hasUnit | M143: unit:L-PER-SEC
A144: entity:SSC_AHUB0001 | B144: brick:Air_Handling_Unit | C144: brick:hasPoint | D144: entity:SSC_AHUB0001_SA_RH | E144: brick:Supply_Air_Humidity_Sensor | H144: rdfs:label_en | I144: Supply Air Humidity | L144: brick:hasUnit | M144: unit:PERCENT_RH
A145: entity:SSC_AHUB0001 | B145: brick:Air_Handling_Unit | C145: brick:hasPoint | D145: entity:SSC_AHUB0001_SAT | E145: brick:Supply_Air_Temperature_Sensor | H145: rdfs:label_en | I145: Supply Air Temperature | L145: brick:hasUnit | M145: unit:DEG_C
A146: entity:SSC_AHUB0001 | B146: brick:Air_Handling_Unit | C146: brick:hasPoint | D146: entity:SSC_AHUB0001_Occupancy_Mode | E146: brick:Occupancy_Status | H146: rdfs:label_en | I146: Occupancy Mode | L146: brick:hasUnit | M146: unit:UNITLESS
A147: entity:SSC_AHUB0001 | B147: brick:Air_Handling_Unit | C147: brick:hasPoint | D147: entity:SSC_AHUB0001_Dehum_Setpoint | E147: brick:Humidity_Setpoint | H147: rdfs:label_en | I147: Dehumidification Setpoint | L147: brick:hasUnit | M147: unit:PERCENT_RH
...

Sheet CCU_Comparison
A1: CCU / CRAC Ontology Consistency Check — 14 units
A2: Source: SSC_Ontology_Ver0.5!A815:E1346 (532 triples). Relations normalised by replacing the unit id with {U}, then counted per unit. rec:locatedIn relations are excluded - location legitimately differs by unit.
A4: 1. Triple count per unit
A5: Metric | B5: CCU3F0301 | C5: CCU3F0302 | D5: CCUB0001A | E5: CCUB0001B | F5: CCUB0002A | G5: CCUB0002B | H5: CCUB0003 | I5: CCUB0004 | J5: CCUB0005A | K5: CCUB0005B | L5: CCUB0006A | M5: CCUB0006B | N5: CCUB0007 | O5: CCUB0008 | P5: Check
A6: Rows in source | B6: =COUNTIF(SSC_Ontology_Ver0.5!$A$815:$A$1346,"*CCU3F0301*") -> 38 | C6: =COUNTIF(SSC_Ontology_Ver0.5!$A$815:$A$1346,"*CCU3F0302*") -> 38 | D6: =COUNTIF(SSC_Ontology_Ver0.5!$A$815:$A$1346,"*CCUB0001A*") -> 38 | E6: =COUNTIF(SSC_Ontology_Ver0.5!$A$815:$A$1346,"*CCUB0001B*") -> 38 | F6: =COUNTIF(SSC_Ontology_Ver0.5!$A$815:$A$1346,"*CCUB0002A*") -> 38 | G6: =COUNTIF(SSC_Ontology_Ver0.5!$A$815:$A$1346,"*CCUB0002B*") -> 38 | H6: =COUNTIF(SSC_Ontology_Ver0.5!$A$815:$A$1346,"*CCUB0003*") -> 38 | I6: =COUNTIF(SSC_Ontology_Ver0.5!$A$815:$A$1346,"*CCUB0004*") -> 38 | J6: =COUNTIF(SSC_Ontology_Ver0.5!$A$815:$A$1346,"*CCUB0005A*") -> 38 | K6: =COUNTIF(SSC_Ontology_Ver0.5!$A$815:$A$1346,"*CCUB0005B*") -> 38 | L6: =COUNTIF(SSC_Ontology_Ver0.5!$A$815:$A$1346,"*CCUB0006A*") -> 38 | M6: =COUNTIF(SSC_Ontology_Ver0.5!$A$815:$A$1346,"*CCUB0006B*") -> 38 | N6: =COUNTIF(SSC_Ontology_Ver0.5!$A$815:$A$1346,"*CCUB0007*") -> 38 | O6: =COUNTIF(SSC_Ontology_Ver0.5!$A$815:$A$1346,"*CCUB0008*") -> 38 | P6: =IF(MIN(B6:O6)=MAX(B6:O6),"All equal ("&B6&" rows)","MISMATCH") -> All equal (38 rows)
A7: Difference vs CCU3F0301 | B7: =B6-$B$6 -> 0 | C7: =C6-$B$6 -> 0 | D7: =D6-$B$6 -> 0 | E7: =E6-$B$6 -> 0 | F7: =F6-$B$6 -> 0 | G7: =G6-$B$6 -> 0 | H7: =H6-$B$6 -> 0 | I7: =I6-$B$6 -> 0 | ... O7: =O6-$B$6 -> 0
A9: 2. Findings
A10: Triple count: IDENTICAL — all 14 units have exactly 38 rows.
A11: Relation patterns: 40 unique patterns; 37 present exactly once on every unit. No missing points, no duplicated rows.
A12: The only variation is rec:locatedIn (3 distinct rooms: B1_038_SER-2, B1_023_Q_TEL, B1_017_MDF-2) — excluded as agreed.
A13: Type columns (subject type, object type): consistent — every pattern uses the same brick/para class on all 14 units.
A15: 3. Full relation matrix — every unique CCU relation pattern and its count per unit
A16: Subject pattern | B16: Predicate | C16: Object pattern | D16: CCU3F0301 | E16: CCU3F0302 | F16: CCUB0001A | G16: CCUB0001B | H16: CCUB0002A | I16: CCUB0002B | J16: CCUB0003 | K16: CCUB0004 | L16: CCUB0005A | M16: CCUB0005B | N16: CCUB0006A | O16: CCUB0006B | P16: CCUB0007 | Q16: CCUB0008 | R16: Status
A17: entity:SSC_{U} | B17: brick:hasPoint | C17: entity:SSC_{U}_Humidity | D17: =COUNTIFS(SSC_Ontology_Ver0.5!$A$815:$A$1346,SUBSTITUTE($A17,"{U}",D$16),SSC_Ontology_Ver0.5!$C$815:$C$1346,$B17,SSC_Ontology_Ver0.5!$D$815:$D$1346,SUBSTITUTE($C17,"{U}",D$16)) -> 1 | E17: =COUNTIFS(SSC_Ontology_Ver0.5!$A$815:$A$1346,SUBSTITUTE($A17,"{U}",E$16),SSC_Ontology_Ver0.5!$C$815:$C$1346,$B17,SSC_Ontology_Ver0.5!$D$815:$D$1346,SUBSTITUTE($C17,"{U}",E$16)) -> 1 | F17: =COUNTIFS(SSC_Ontology_Ver0.5!$A$815:$A$1346,SUBSTITUTE($A17,"{U}",F$16),SSC_Ontology_Ver0.5!$C$815:$C$1346,$B17,SSC_Ontology_Ver0.5!$D$815:$D$1346,SUBSTITUTE($C17,"{U}",F$16)) -> 1 | G17: =COUNTIFS(SSC_Ontology_Ver0.5!$A$815:$A$1346,SUBSTITUTE($A17,"{U}",G$16),SSC_Ontology_Ver0.5!$C$815:$C$1346,$B17,SSC_Ontology_Ver0.5!$D$815:$D$1346,SUBSTITUTE($C17,"{U}",G$16)) -> 1 | H17: =COUNTIFS(SSC_Ontology_Ver0.5!$A$815:$A$1346,SUBSTITUTE($A17,"{U}",H$16),SSC_Ontology_Ver0.5!$C$815:$C$1346,$B17,SSC_Ontology_Ver0.5!$D$815:$D$1346,SUBSTITUTE($C17,"{U}",H$16)) -> 1 | I17: =COUNTIFS(SSC_Ontology_Ver0.5!$A$815:$A$1346,SUBSTITUTE($A17,"{U}",I$16),SSC_Ontology_Ver0.5!$C$815:$C$1346,$B17,SSC_Ontology_Ver0.5!$D$815:$D$1346,SUBSTITUTE($C17,"{U}",I$16)) -> 1 | J17: =COUNTIFS(SSC_Ontology_Ver0.5!$A$815:$A$1346,SUBSTITUTE($A17,"{U}",J$16),SSC_Ontology_Ver0.5!$C$815:$C$1346,$B17,SSC_Ontology_Ver0.5!$D$815:$D$1346,SUBSTITUTE($C17,"{U}",J$16)) -> 1 | K17: =COUNTIFS(SSC_Ontology_Ver0.5!$A$815:$A$1346,SUBSTITUTE($A17,"{U}",K$16),SSC_Ontology_Ver0.5!$C$815:$C$1346,$B17,SSC_Ontology_Ver0.5!$D$815:$D$1346,SUBSTITUTE($C17,"{U}",K$16)) -> 1 | ... Q17: =COUNTIFS(SSC_Ontology_Ver0.5!$A$815:$A$1346,SUBSTITUTE($A17,"{U}",Q$16),SSC_Ontology_Ver0.5!$C$815:$C$1346,$B17,SSC_Ontology_Ver0.5!$D$815:$D$1346,SUBSTITUTE($C17,"{U}",Q$16)) -> 1 | R17: =IF($B17="rec:locatedIn","Excluded - location varies by unit",IF(AND(MIN(D17:Q17)=MAX(D17:Q17),MAX(D17:Q17)=1),"OK",IF(MIN(D17:Q17)=0,"Not on all units","Duplicated"))) -> OK
A18: entity:SSC_{U} | B18: brick:hasPoint | C18: entity:SSC_{U}_Temperature | D18: =COUNTIFS(SSC_Ontology_Ver0.5!$A$815:$A$1346,SUBSTITUTE($A18,"{U}",D$16),SSC_Ontology_Ver0.5!$C$815:$C$1346,$B18,SSC_Ontology_Ver0.5!$D$815:$D$1346,SUBSTITUTE($C18,"{U}",D$16)) -> 1 | E18: =COUNTIFS(SSC_Ontology_Ver0.5!$A$815:$A$1346,SUBSTITUTE($A18,"{U}",E$16),SSC_Ontology_Ver0.5!$C$815:$C$1346,$B18,SSC_Ontology_Ver0.5!$D$815:$D$1346,SUBSTITUTE($C18,"{U}",E$16)) -> 1 | F18: =COUNTIFS(SSC_Ontology_Ver0.5!$A$815:$A$1346,SUBSTITUTE($A18,"{U}",F$16),SSC_Ontology_Ver0.5!$C$815:$C$1346,$B18,SSC_Ontology_Ver0.5!$D$815:$D$1346,SUBSTITUTE($C18,"{U}",F$16)) -> 1 | G18: =COUNTIFS(SSC_Ontology_Ver0.5!$A$815:$A$1346,SUBSTITUTE($A18,"{U}",G$16),SSC_Ontology_Ver0.5!$C$815:$C$1346,$B18,SSC_Ontology_Ver0.5!$D$815:$D$1346,SUBSTITUTE($C18,"{U}",G$16)) -> 1 | H18: =COUNTIFS(SSC_Ontology_Ver0.5!$A$815:$A$1346,SUBSTITUTE($A18,"{U}",H$16),SSC_Ontology_Ver0.5!$C$815:$C$1346,$B18,SSC_Ontology_Ver0.5!$D$815:$D$1346,SUBSTITUTE($C18,"{U}",H$16)) -> 1 | I18: =COUNTIFS(SSC_Ontology_Ver0.5!$A$815:$A$1346,SUBSTITUTE($A18,"{U}",I$16),SSC_Ontology_Ver0.5!$C$815:$C$1346,$B18,SSC_Ontology_Ver0.5!$D$815:$D$1346,SUBSTITUTE($C18,"{U}",I$16)) -> 1 | J18: =COUNTIFS(SSC_Ontology_Ver0.5!$A$815:$A$1346,SUBSTITUTE($A18,"{U}",J$16),SSC_Ontology_Ver0.5!$C$815:$C$1346,$B18,SSC_Ontology_Ver0.5!$D$815:$D$1346,SUBSTITUTE($C18,"{U}",J$16)) -> 1 | K18: =COUNTIFS(SSC_Ontology_Ver0.5!$A$815:$A$1346,SUBSTITUTE($A18,"{U}",K$16),SSC_Ontology_Ver0.5!$C$815:$C$1346,$B18,SSC_Ontology_Ver0.5!$D$815:$D$1346,SUBSTITUTE($C18,"{U}",K$16)) -> 1 | ... Q18: =COUNTIFS(SSC_Ontology_Ver0.5!$A$815:$A$1346,SUBSTITUTE($A18,"{U}",Q$16),SSC_Ontology_Ver0.5!$C$815:$C$1346,$B18,SSC_Ontology_Ver0.5!$D$815:$D$1346,SUBSTITUTE($C18,"{U}",Q$16)) -> 1 | R18: =IF($B18="rec:locatedIn","Excluded - location varies by unit",IF(AND(MIN(D18:Q18)=MAX(D18:Q18),MAX(D18:Q18)=1),"OK",IF(MIN(D18:Q18)=0,"Not on all units","Duplicated"))) -> OK
A19: entity:SSC_{U} | B19: brick:hasPoint | C19: entity:SSC_{U}_Humidity_Setpoint | D19: =COUNTIFS(SSC_Ontology_Ver0.5!$A$815:$A$1346,SUBSTITUTE($A19,"{U}",D$16),SSC_Ontology_Ver0.5!$C$815:$C$1346,$B19,SSC_Ontology_Ver0.5!$D$815:$D$1346,SUBSTITUTE($C19,"{U}",D$16)) -> 1 | E19: =COUNTIFS(SSC_Ontology_Ver0.5!$A$815:$A$1346,SUBSTITUTE($A19,"{U}",E$16),SSC_Ontology_Ver0.5!$C$815:$C$1346,$B19,SSC_Ontology_Ver0.5!$D$815:$D$1346,SUBSTITUTE($C19,"{U}",E$16)) -> 1 | F19: =COUNTIFS(SSC_Ontology_Ver0.5!$A$815:$A$1346,SUBSTITUTE($A19,"{U}",F$16),SSC_Ontology_Ver0.5!$C$815:$C$1346,$B19,SSC_Ontology_Ver0.5!$D$815:$D$1346,SUBSTITUTE($C19,"{U}",F$16)) -> 1 | G19: =COUNTIFS(SSC_Ontology_Ver0.5!$A$815:$A$1346,SUBSTITUTE($A19,"{U}",G$16),SSC_Ontology_Ver0.5!$C$815:$C$1346,$B19,SSC_Ontology_Ver0.5!$D$815:$D$1346,SUBSTITUTE($C19,"{U}",G$16)) -> 1 | H19: =COUNTIFS(SSC_Ontology_Ver0.5!$A$815:$A$1346,SUBSTITUTE($A19,"{U}",H$16),SSC_Ontology_Ver0.5!$C$815:$C$1346,$B19,SSC_Ontology_Ver0.5!$D$815:$D$1346,SUBSTITUTE($C19,"{U}",H$16)) -> 1 | I19: =COUNTIFS(SSC_Ontology_Ver0.5!$A$815:$A$1346,SUBSTITUTE($A19,"{U}",I$16),SSC_Ontology_Ver0.5!$C$815:$C$1346,$B19,SSC_Ontology_Ver0.5!$D$815:$D$1346,SUBSTITUTE($C19,"{U}",I$16)) -> 1 | J19: =COUNTIFS(SSC_Ontology_Ver0.5!$A$815:$A$1346,SUBSTITUTE($A19,"{U}",J$16),SSC_Ontology_Ver0.5!$C$815:$C$1346,$B19,SSC_Ontology_Ver0.5!$D$815:$D$1346,SUBSTITUTE($C19,"{U}",J$16)) -> 1 | K19: =COUNTIFS(SSC_Ontology_Ver0.5!$A$815:$A$1346,SUBSTITUTE($A19,"{U}",K$16),SSC_Ontology_Ver0.5!$C$815:$C$1346,$B19,SSC_Ontology_Ver0.5!$D$815:$D$1346,SUBSTITUTE($C19,"{U}",K$16)) -> 1 | ... Q19: =COUNTIFS(SSC_Ontology_Ver0.5!$A$815:$A$1346,SUBSTITUTE($A19,"{U}",Q$16),SSC_Ontology_Ver0.5!$C$815:$C$1346,$B19,SSC_Ontology_Ver0.5!$D$815:$D$1346,SUBSTITUTE($C19,"{U}",Q$16)) -> 1 | R19: =IF($B19="rec:locatedIn","Excluded - location varies by unit",IF(AND(MIN(D19:Q19)=MAX(D19:Q19),MAX(D19:Q19)=1),"OK",IF(MIN(D19:Q19)=0,"Not on all units","Duplicated"))) -> OK
A20: entity:SSC_{U} | B20: brick:hasPoint | C20: entity:SSC_{U}_Temperature_Setpoint | D20: =COUNTIFS(SSC_Ontology_Ver0.5!$A$815:$A$1346,SUBSTITUTE($A20,"{U}",D$16),SSC_Ontology_Ver0.5!$C$815:$C$1346,$B20,SSC_Ontology_Ver0.5!$D$815:$D$1346,SUBSTITUTE($C20,"{U}",D$16)) -> 1 | E20: =COUNTIFS(SSC_Ontology_Ver0.5!$A$815:$A$1346,SUBSTITUTE($A20,"{U}",E$16),SSC_Ontology_Ver0.5!$C$815:$C$1346,$B20,SSC_Ontology_Ver0.5!$D$815:$D$1346,SUBSTITUTE($C20,"{U}",E$16)) -> 1 | F20: =COUNTIFS(SSC_Ontology_Ver0.5!$A$815:$A$1346,SUBSTITUTE($A20,"{U}",F$16),SSC_Ontology_Ver0.5!$C$815:$C$1346,$B20,SSC_Ontology_Ver0.5!$D$815:$D$1346,SUBSTITUTE($C20,"{U}",F$16)) -> 1 | G20: =COUNTIFS(SSC_Ontology_Ver0.5!$A$815:$A$1346,SUBSTITUTE($A20,"{U}",G$16),SSC_Ontology_Ver0.5!$C$815:$C$1346,$B20,SSC_Ontology_Ver0.5!$D$815:$D$1346,SUBSTITUTE($C20,"{U}",G$16)) -> 1 | H20: =COUNTIFS(SSC_Ontology_Ver0.5!$A$815:$A$1346,SUBSTITUTE($A20,"{U}",H$16),SSC_Ontology_Ver0.5!$C$815:$C$1346,$B20,SSC_Ontology_Ver0.5!$D$815:$D$1346,SUBSTITUTE($C20,"{U}",H$16)) -> 1 | I20: =COUNTIFS(SSC_Ontology_Ver0.5!$A$815:$A$1346,SUBSTITUTE($A20,"{U}",I$16),SSC_Ontology_Ver0.5!$C$815:$C$1346,$B20,SSC_Ontology_Ver0.5!$D$815:$D$1346,SUBSTITUTE($C20,"{U}",I$16)) -> 1 | J20: =COUNTIFS(SSC_Ontology_Ver0.5!$A$815:$A$1346,SUBSTITUTE($A20,"{U}",J$16),SSC_Ontology_Ver0.5!$C$815:$C$1346,$B20,SSC_Ontology_Ver0.5!$D$815:$D$1346,SUBSTITUTE($C20,"{U}",J$16)) -> 1 | K20: =COUNTIFS(SSC_Ontology_Ver0.5!$A$815:$A$1346,SUBSTITUTE($A20,"{U}",K$16),SSC_Ontology_Ver0.5!$C$815:$C$1346,$B20,SSC_Ontology_Ver0.5!$D$815:$D$1346,SUBSTITUTE($C20,"{U}",K$16)) -> 1 | ... Q20: =COUNTIFS(SSC_Ontology_Ver0.5!$A$815:$A$1346,SUBSTITUTE($A20,"{U}",Q$16),SSC_Ontology_Ver0.5!$C$815:$C$1346,$B20,SSC_Ontology_Ver0.5!$D$815:$D$1346,SUBSTITUTE($C20,"{U}",Q$16)) -> 1 | R20: =IF($B20="rec:locatedIn","Excluded - location varies by unit",IF(AND(MIN(D20:Q20)=MAX(D20:Q20),MAX(D20:Q20)=1),"OK",IF(MIN(D20:Q20)=0,"Not on all units","Duplicated"))) -> OK
A21: entity:SSC_{U} | B21: brick:hasPoint | C21: entity:SSC_{U}_Communication_Alarm | D21: =COUNTIFS(SSC_Ontology_Ver0.5!$A$815:$A$1346,SUBSTITUTE($A21,"{U}",D$16),SSC_Ontology_Ver0.5!$C$815:$C$1346,$B21,SSC_Ontology_Ver0.5!$D$815:$D$1346,SUBSTITUTE($C21,"{U}",D$16)) -> 1 | E21: =COUNTIFS(SSC_Ontology_Ver0.5!$A$815:$A$1346,SUBSTITUTE($A21,"{U}",E$16),SSC_Ontology_Ver0.5!$C$815:$C$1346,$B21,SSC_Ontology_Ver0.5!$D$815:$D$1346,SUBSTITUTE($C21,"{U}",E$16)) -> 1 | F21: =COUNTIFS(SSC_Ontology_Ver0.5!$A$815:$A$1346,SUBSTITUTE($A21,"{U}",F$16),SSC_Ontology_Ver0.5!$C$815:$C$1346,$B21,SSC_Ontology_Ver0.5!$D$815:$D$1346,SUBSTITUTE($C21,"{U}",F$16)) -> 1 | G21: =COUNTIFS(SSC_Ontology_Ver0.5!$A$815:$A$1346,SUBSTITUTE($A21,"{U}",G$16),SSC_Ontology_Ver0.5!$C$815:$C$1346,$B21,SSC_Ontology_Ver0.5!$D$815:$D$1346,SUBSTITUTE($C21,"{U}",G$16)) -> 1 | H21: =COUNTIFS(SSC_Ontology_Ver0.5!$A$815:$A$1346,SUBSTITUTE($A21,"{U}",H$16),SSC_Ontology_Ver0.5!$C$815:$C$1346,$B21,SSC_Ontology_Ver0.5!$D$815:$D$1346,SUBSTITUTE($C21,"{U}",H$16)) -> 1 | I21: =COUNTIFS(SSC_Ontology_Ver0.5!$A$815:$A$1346,SUBSTITUTE($A21,"{U}",I$16),SSC_Ontology_Ver0.5!$C$815:$C$1346,$B21,SSC_Ontology_Ver0.5!$D$815:$D$1346,SUBSTITUTE($C21,"{U}",I$16)) -> 1 | J21: =COUNTIFS(SSC_Ontology_Ver0.5!$A$815:$A$1346,SUBSTITUTE($A21,"{U}",J$16),SSC_Ontology_Ver0.5!$C$815:$C$1346,$B21,SSC_Ontology_Ver0.5!$D$815:$D$1346,SUBSTITUTE($C21,"{U}",J$16)) -> 1 | K21: =COUNTIFS(SSC_Ontology_Ver0.5!$A$815:$A$1346,SUBSTITUTE($A21,"{U}",K$16),SSC_Ontology_Ver0.5!$C$815:$C$1346,$B21,SSC_Ontology_Ver0.5!$D$815:$D$1346,SUBSTITUTE($C21,"{U}",K$16)) -> 1 | ... Q21: =COUNTIFS(SSC_Ontology_Ver0.5!$A$815:$A$1346,SUBSTITUTE($A21,"{U}",Q$16),SSC_Ontology_Ver0.5!$C$815:$C$1346,$B21,SSC_Ontology_Ver0.5!$D$815:$D$1346,SUBSTITUTE($C21,"{U}",Q$16)) -> 1 | R21: =IF($B21="rec:locatedIn","Excluded - location varies by unit",IF(AND(MIN(D21:Q21)=MAX(D21:Q21),MAX(D21:Q21)=1),"OK",IF(MIN(D21:Q21)=0,"Not on all units","Duplicated"))) -> OK
A22: entity:SSC_{U} | B22: brick:hasPoint | C22: entity:SSC_{U}_Loss_of_Airflow | D22: =COUNTIFS(SSC_Ontology_Ver0.5!$A$815:$A$1346,SUBSTITUTE($A22,"{U}",D$16),SSC_Ontology_Ver0.5!$C$815:$C$1346,$B22,SSC_Ontology_Ver0.5!$D$815:$D$1346,SUBSTITUTE($C22,"{U}",D$16)) -> 1 | E22: =COUNTIFS(SSC_Ontology_Ver0.5!$A$815:$A$1346,SUBSTITUTE($A22,"{U}",E$16),SSC_Ontology_Ver0.5!$C$815:$C$1346,$B22,SSC_Ontology_Ver0.5!$D$815:$D$1346,SUBSTITUTE($C22,"{U}",E$16)) -> 1 | F22: =COUNTIFS(SSC_Ontology_Ver0.5!$A$815:$A$1346,SUBSTITUTE($A22,"{U}",F$16),SSC_Ontology_Ver0.5!$C$815:$C$1346,$B22,SSC_Ontology_Ver0.5!$D$815:$D$1346,SUBSTITUTE($C22,"{U}",F$16)) -> 1 | G22: =COUNTIFS(SSC_Ontology_Ver0.5!$A$815:$A$1346,SUBSTITUTE($A22,"{U}",G$16),SSC_Ontology_Ver0.5!$C$815:$C$1346,$B22,SSC_Ontology_Ver0.5!$D$815:$D$1346,SUBSTITUTE($C22,"{U}",G$16)) -> 1 | H22: =COUNTIFS(SSC_Ontology_Ver0.5!$A$815:$A$1346,SUBSTITUTE($A22,"{U}",H$16),SSC_Ontology_Ver0.5!$C$815:$C$1346,$B22,SSC_Ontology_Ver0.5!$D$815:$D$1346,SUBSTITUTE($C22,"{U}",H$16)) -> 1 | I22: =COUNTIFS(SSC_Ontology_Ver0.5!$A$815:$A$1346,SUBSTITUTE($A22,"{U}",I$16),SSC_Ontology_Ver0.5!$C$815:$C$1346,$B22,SSC_Ontology_Ver0.5!$D$815:$D$1346,SUBSTITUTE($C22,"{U}",I$16)) -> 1 | J22: =COUNTIFS(SSC_Ontology_Ver0.5!$A$815:$A$1346,SUBSTITUTE($A22,"{U}",J$16),SSC_Ontology_Ver0.5!$C$815:$C$1346,$B22,SSC_Ontology_Ver0.5!$D$815:$D$1346,SUBSTITUTE($C22,"{U}",J$16)) -> 1 | K22: =COUNTIFS(SSC_Ontology_Ver0.5!$A$815:$A$1346,SUBSTITUTE($A22,"{U}",K$16),SSC_Ontology_Ver0.5!$C$815:$C$1346,$B22,SSC_Ontology_Ver0.5!$D$815:$D$1346,SUBSTITUTE($C22,"{U}",K$16)) -> 1 | ... Q22: =COUNTIFS(SSC_Ontology_Ver0.5!$A$815:$A$1346,SUBSTITUTE($A22,"{U}",Q$16),SSC_Ontology_Ver0.5!$C$815:$C$1346,$B22,SSC_Ontology_Ver0.5!$D$815:$D$1346,SUBSTITUTE($C22,"{U}",Q$16)) -> 1 | R22: =IF($B22="rec:locatedIn","Excluded - location varies by unit",IF(AND(MIN(D22:Q22)=MAX(D22:Q22),MAX(D22:Q22)=1),"OK",IF(MIN(D22:Q22)=0,"Not on all units","Duplicated"))) -> OK
A23: entity:SSC_{U} | B23: brick:hasPoint | C23: entity:SSC_{U}_General_Fault | D23: =COUNTIFS(SSC_Ontology_Ver0.5!$A$815:$A$1346,SUBSTITUTE($A23,"{U}",D$16),SSC_Ontology_Ver0.5!$C$815:$C$1346,$B23,SSC_Ontology_Ver0.5!$D$815:$D$1346,SUBSTITUTE($C23,"{U}",D$16)) -> 1 | E23: =COUNTIFS(SSC_Ontology_Ver0.5!$A$815:$A$1346,SUBSTITUTE($A23,"{U}",E$16),SSC_Ontology_Ver0.5!$C$815:$C$1346,$B23,SSC_Ontology_Ver0.5!$D$815:$D$1346,SUBSTITUTE($C23,"{U}",E$16)) -> 1 | F23: =COUNTIFS(SSC_Ontology_Ver0.5!$A$815:$A$1346,SUBSTITUTE($A23,"{U}",F$16),SSC_Ontology_Ver0.5!$C$815:$C$1346,$B23,SSC_Ontology_Ver0.5!$D$815:$D$1346,SUBSTITUTE($C23,"{U}",F$16)) -> 1 | G23: =COUNTIFS(SSC_Ontology_Ver0.5!$A$815:$A$1346,SUBSTITUTE($A23,"{U}",G$16),SSC_Ontology_Ver0.5!$C$815:$C$1346,$B23,SSC_Ontology_Ver0.5!$D$815:$D$1346,SUBSTITUTE($C23,"{U}",G$16)) -> 1 | H23: =COUNTIFS(SSC_Ontology_Ver0.5!$A$815:$A$1346,SUBSTITUTE($A23,"{U}",H$16),SSC_Ontology_Ver0.5!$C$815:$C$1346,$B23,SSC_Ontology_Ver0.5!$D$815:$D$1346,SUBSTITUTE($C23,"{U}",H$16)) -> 1 | I23: =COUNTIFS(SSC_Ontology_Ver0.5!$A$815:$A$1346,SUBSTITUTE($A23,"{U}",I$16),SSC_Ontology_Ver0.5!$C$815:$C$1346,$B23,SSC_Ontology_Ver0.5!$D$815:$D$1346,SUBSTITUTE($C23,"{U}",I$16)) -> 1 | J23: =COUNTIFS(SSC_Ontology_Ver0.5!$A$815:$A$1346,SUBSTITUTE($A23,"{U}",J$16),SSC_Ontology_Ver0.5!$C$815:$C$1346,$B23,SSC_Ontology_Ver0.5!$D$815:$D$1346,SUBSTITUTE($C23,"{U}",J$16)) -> 1 | K23: =COUNTIFS(SSC_Ontology_Ver0.5!$A$815:$A$1346,SUBSTITUTE($A23,"{U}",K$16),SSC_Ontology_Ver0.5!$C$815:$C$1346,$B23,SSC_Ontology_Ver0.5!$D$815:$D$1346,SUBSTITUTE($C23,"{U}",K$16)) -> 1 | ... Q23: =COUNTIFS(SSC_Ontology_Ver0.5!$A$815:$A$1346,SUBSTITUTE($A23,"{U}",Q$16),SSC_Ontology_Ver0.5!$C$815:$C$1346,$B23,SSC_Ontology_Ver0.5!$D$815:$D$1346,SUBSTITUTE($C23,"{U}",Q$16)) -> 1 | R23: =IF($B23="rec:locatedIn","Excluded - location varies by unit",IF(AND(MIN(D23:Q23)=MAX(D23:Q23),MAX(D23:Q23)=1),"OK",IF(MIN(D23:Q23)=0,"Not on all units","Duplicated"))) -> OK
A24: entity:SSC_{U} | B24: brick:hasPoint | C24: entity:SSC_{U}_Clogged_Filter | D24: =COUNTIFS(SSC_Ontology_Ver0.5!$A$815:$A$1346,SUBSTITUTE($A24,"{U}",D$16),SSC_Ontology_Ver0.5!$C$815:$C$1346,$B24,SSC_Ontology_Ver0.5!$D$815:$D$1346,SUBSTITUTE($C24,"{U}",D$16)) -> 1 | E24: =COUNTIFS(SSC_Ontology_Ver0.5!$A$815:$A$1346,SUBSTITUTE($A24,"{U}",E$16),SSC_Ontology_Ver0.5!$C$815:$C$1346,$B24,SSC_Ontology_Ver0.5!$D$815:$D$1346,SUBSTITUTE($C24,"{U}",E$16)) -> 1 | F24: =COUNTIFS(SSC_Ontology_Ver0.5!$A$815:$A$1346,SUBSTITUTE($A24,"{U}",F$16),SSC_Ontology_Ver0.5!$C$815:$C$1346,$B24,SSC_Ontology_Ver0.5!$D$815:$D$1346,SUBSTITUTE($C24,"{U}",F$16)) -> 1 | G24: =COUNTIFS(SSC_Ontology_Ver0.5!$A$815:$A$1346,SUBSTITUTE($A24,"{U}",G$16),SSC_Ontology_Ver0.5!$C$815:$C$1346,$B24,SSC_Ontology_Ver0.5!$D$815:$D$1346,SUBSTITUTE($C24,"{U}",G$16)) -> 1 | H24: =COUNTIFS(SSC_Ontology_Ver0.5!$A$815:$A$1346,SUBSTITUTE($A24,"{U}",H$16),SSC_Ontology_Ver0.5!$C$815:$C$1346,$B24,SSC_Ontology_Ver0.5!$D$815:$D$1346,SUBSTITUTE($C24,"{U}",H$16)) -> 1 | I24: =COUNTIFS(SSC_Ontology_Ver0.5!$A$815:$A$1346,SUBSTITUTE($A24,"{U}",I$16),SSC_Ontology_Ver0.5!$C$815:$C$1346,$B24,SSC_Ontology_Ver0.5!$D$815:$D$1346,SUBSTITUTE($C24,"{U}",I$16)) -> 1 | J24: =COUNTIFS(SSC_Ontology_Ver0.5!$A$815:$A$1346,SUBSTITUTE($A24,"{U}",J$16),SSC_Ontology_Ver0.5!$C$815:$C$1346,$B24,SSC_Ontology_Ver0.5!$D$815:$D$1346,SUBSTITUTE($C24,"{U}",J$16)) -> 1 | K24: =COUNTIFS(SSC_Ontology_Ver0.5!$A$815:$A$1346,SUBSTITUTE($A24,"{U}",K$16),SSC_Ontology_Ver0.5!$C$815:$C$1346,$B24,SSC_Ontology_Ver0.5!$D$815:$D$1346,SUBSTITUTE($C24,"{U}",K$16)) -> 1 | ... Q24: =COUNTIFS(SSC_Ontology_Ver0.5!$A$815:$A$1346,SUBSTITUTE($A24,"{U}",Q$16),SSC_Ontology_Ver0.5!$C$815:$C$1346,$B24,SSC_Ontology_Ver0.5!$D$815:$D$1346,SUBSTITUTE($C24,"{U}",Q$16)) -> 1 | R24: =IF($B24="rec:locatedIn","Excluded - location varies by unit",IF(AND(MIN(D24:Q24)=MAX(D24:Q24),MAX(D24:Q24)=1),"OK",IF(MIN(D24:Q24)=0,"Not on all units","Duplicated"))) -> OK
A25: entity:SSC_{U} | B25: brick:hasPoint | C25: entity:SSC_{U}_Cool_On_Status | D25: =COUNTIFS(SSC_Ontology_Ver0.5!$A$815:$A$1346,SUBSTITUTE($A25,"{U}",D$16),SSC_Ontology_Ver0.5!$C$815:$C$1346,$B25,SSC_Ontology_Ver0.5!$D$815:$D$1346,SUBSTITUTE($C25,"{U}",D$16)) -> 1 | E25: =COUNTIFS(SSC_Ontology_Ver0.5!$A$815:$A$1346,SUBSTITUTE($A25,"{U}",E$16),SSC_Ontology_Ver0.5!$C$815:$C$1346,$B25,SSC_Ontology_Ver0.5!$D$815:$D$1346,SUBSTITUTE($C25,"{U}",E$16)) -> 1 | F25: =COUNTIFS(SSC_Ontology_Ver0.5!$A$815:$A$1346,SUBSTITUTE($A25,"{U}",F$16),SSC_Ontology_Ver0.5!$C$815:$C$1346,$B25,SSC_Ontology_Ver0.5!$D$815:$D$1346,SUBSTITUTE($C25,"{U}",F$16)) -> 1 | G25: =COUNTIFS(SSC_Ontology_Ver0.5!$A$815:$A$1346,SUBSTITUTE($A25,"{U}",G$16),SSC_Ontology_Ver0.5!$C$815:$C$1346,$B25,SSC_Ontology_Ver0.5!$D$815:$D$1346,SUBSTITUTE($C25,"{U}",G$16)) -> 1 | H25: =COUNTIFS(SSC_Ontology_Ver0.5!$A$815:$A$1346,SUBSTITUTE($A25,"{U}",H$16),SSC_Ontology_Ver0.5!$C$815:$C$1346,$B25,SSC_Ontology_Ver0.5!$D$815:$D$1346,SUBSTITUTE($C25,"{U}",H$16)) -> 1 | I25: =COUNTIFS(SSC_Ontology_Ver0.5!$A$815:$A$1346,SUBSTITUTE($A25,"{U}",I$16),SSC_Ontology_Ver0.5!$C$815:$C$1346,$B25,SSC_Ontology_Ver0.5!$D$815:$D$1346,SUBSTITUTE($C25,"{U}",I$16)) -> 1 | J25: =COUNTIFS(SSC_Ontology_Ver0.5!$A$815:$A$1346,SUBSTITUTE($A25,"{U}",J$16),SSC_Ontology_Ver0.5!$C$815:$C$1346,$B25,SSC_Ontology_Ver0.5!$D$815:$D$1346,SUBSTITUTE($C25,"{U}",J$16)) -> 1 | K25: =COUNTIFS(SSC_Ontology_Ver0.5!$A$815:$A$1346,SUBSTITUTE($A25,"{U}",K$16),SSC_Ontology_Ver0.5!$C$815:$C$1346,$B25,SSC_Ontology_Ver0.5!$D$815:$D$1346,SUBSTITUTE($C25,"{U}",K$16)) -> 1 | ... Q25: =COUNTIFS(SSC_Ontology_Ver0.5!$A$815:$A$1346,SUBSTITUTE($A25,"{U}",Q$16),SSC_Ontology_Ver0.5!$C$815:$C$1346,$B25,SSC_Ontology_Ver0.5!$D$815:$D$1346,SUBSTITUTE($C25,"{U}",Q$16)) -> 1 | R25: =IF($B25="rec:locatedIn","Excluded - location varies by unit",IF(AND(MIN(D25:Q25)=MAX(D25:Q25),MAX(D25:Q25)=1),"OK",IF(MIN(D25:Q25)=0,"Not on all units","Duplicated"))) -> OK
A26: entity:SSC_{U} | B26: brick:hasPoint | C26: entity:SSC_{U}_Dehumidifcation_On_Status | D26: =COUNTIFS(SSC_Ontology_Ver0.5!$A$815:$A$1346,SUBSTITUTE($A26,"{U}",D$16),SSC_Ontology_Ver0.5!$C$815:$C$1346,$B26,SSC_Ontology_Ver0.5!$D$815:$D$1346,SUBSTITUTE($C26,"{U}",D$16)) -> 1 | E26: =COUNTIFS(SSC_Ontology_Ver0.5!$A$815:$A$1346,SUBSTITUTE($A26,"{U}",E$16),SSC_Ontology_Ver0.5!$C$815:$C$1346,$B26,SSC_Ontology_Ver0.5!$D$815:$D$1346,SUBSTITUTE($C26,"{U}",E$16)) -> 1 | F26: =COUNTIFS(SSC_Ontology_Ver0.5!$A$815:$A$1346,SUBSTITUTE($A26,"{U}",F$16),SSC_Ontology_Ver0.5!$C$815:$C$1346,$B26,SSC_Ontology_Ver0.5!$D$815:$D$1346,SUBSTITUTE($C26,"{U}",F$16)) -> 1 | G26: =COUNTIFS(SSC_Ontology_Ver0.5!$A$815:$A$1346,SUBSTITUTE($A26,"{U}",G$16),SSC_Ontology_Ver0.5!$C$815:$C$1346,$B26,SSC_Ontology_Ver0.5!$D$815:$D$1346,SUBSTITUTE($C26,"{U}",G$16)) -> 1 | H26: =COUNTIFS(SSC_Ontology_Ver0.5!$A$815:$A$1346,SUBSTITUTE($A26,"{U}",H$16),SSC_Ontology_Ver0.5!$C$815:$C$1346,$B26,SSC_Ontology_Ver0.5!$D$815:$D$1346,SUBSTITUTE($C26,"{U}",H$16)) -> 1 | I26: =COUNTIFS(SSC_Ontology_Ver0.5!$A$815:$A$1346,SUBSTITUTE($A26,"{U}",I$16),SSC_Ontology_Ver0.5!$C$815:$C$1346,$B26,SSC_Ontology_Ver0.5!$D$815:$D$1346,SUBSTITUTE($C26,"{U}",I$16)) -> 1 | J26: =COUNTIFS(SSC_Ontology_Ver0.5!$A$815:$A$1346,SUBSTITUTE($A26,"{U}",J$16),SSC_Ontology_Ver0.5!$C$815:$C$1346,$B26,SSC_Ontology_Ver0.5!$D$815:$D$1346,SUBSTITUTE($C26,"{U}",J$16)) -> 1 | K26: =COUNTIFS(SSC_Ontology_Ver0.5!$A$815:$A$1346,SUBSTITUTE($A26,"{U}",K$16),SSC_Ontology_Ver0.5!$C$815:$C$1346,$B26,SSC_Ontology_Ver0.5!$D$815:$D$1346,SUBSTITUTE($C26,"{U}",K$16)) -> 1 | ... Q26: =COUNTIFS(SSC_Ontology_Ver0.5!$A$815:$A$1346,SUBSTITUTE($A26,"{U}",Q$16),SSC_Ontology_Ver0.5!$C$815:$C$1346,$B26,SSC_Ontology_Ver0.5!$D$815:$D$1346,SUBSTITUTE($C26,"{U}",Q$16)) -> 1 | R26: =IF($B26="rec:locatedIn","Excluded - location varies by unit",IF(AND(MIN(D26:Q26)=MAX(D26:Q26),MAX(D26:Q26)=1),"OK",IF(MIN(D26:Q26)=0,"Not on all units","Duplicated"))) -> OK
A27: entity:SSC_{U} | B27: brick:hasPoint | C27: entity:SSC_{U}_Electric_Heater_On_Status | D27: =COUNTIFS(SSC_Ontology_Ver0.5!$A$815:$A$1346,SUBSTITUTE($A27,"{U}",D$16),SSC_Ontology_Ver0.5!$C$815:$C$1346,$B27,SSC_Ontology_Ver0.5!$D$815:$D$1346,SUBSTITUTE($C27,"{U}",D$16)) -> 1 | E27: =COUNTIFS(SSC_Ontology_Ver0.5!$A$815:$A$1346,SUBSTITUTE($A27,"{U}",E$16),SSC_Ontology_Ver0.5!$C$815:$C$1346,$B27,SSC_Ontology_Ver0.5!$D$815:$D$1346,SUBSTITUTE($C27,"{U}",E$16)) -> 1 | F27: =COUNTIFS(SSC_Ontology_Ver0.5!$A$815:$A$1346,SUBSTITUTE($A27,"{U}",F$16),SSC_Ontology_Ver0.5!$C$815:$C$1346,$B27,SSC_Ontology_Ver0.5!$D$815:$D$1346,SUBSTITUTE($C27,"{U}",F$16)) -> 1 | G27: =COUNTIFS(SSC_Ontology_Ver0.5!$A$815:$A$1346,SUBSTITUTE($A27,"{U}",G$16),SSC_Ontology_Ver0.5!$C$815:$C$1346,$B27,SSC_Ontology_Ver0.5!$D$815:$D$1346,SUBSTITUTE($C27,"{U}",G$16)) -> 1 | H27: =COUNTIFS(SSC_Ontology_Ver0.5!$A$815:$A$1346,SUBSTITUTE($A27,"{U}",H$16),SSC_Ontology_Ver0.5!$C$815:$C$1346,$B27,SSC_Ontology_Ver0.5!$D$815:$D$1346,SUBSTITUTE($C27,"{U}",H$16)) -> 1 | I27: =COUNTIFS(SSC_Ontology_Ver0.5!$A$815:$A$1346,SUBSTITUTE($A27,"{U}",I$16),SSC_Ontology_Ver0.5!$C$815:$C$1346,$B27,SSC_Ontology_Ver0.5!$D$815:$D$1346,SUBSTITUTE($C27,"{U}",I$16)) -> 1 | J27: =COUNTIFS(SSC_Ontology_Ver0.5!$A$815:$A$1346,SUBSTITUTE($A27,"{U}",J$16),SSC_Ontology_Ver0.5!$C$815:$C$1346,$B27,SSC_Ontology_Ver0.5!$D$815:$D$1346,SUBSTITUTE($C27,"{U}",J$16)) -> 1 | K27: =COUNTIFS(SSC_Ontology_Ver0.5!$A$815:$A$1346,SUBSTITUTE($A27,"{U}",K$16),SSC_Ontology_Ver0.5!$C$815:$C$1346,$B27,SSC_Ontology_Ver0.5!$D$815:$D$1346,SUBSTITUTE($C27,"{U}",K$16)) -> 1 | ... Q27: =COUNTIFS(SSC_Ontology_Ver0.5!$A$815:$A$1346,SUBSTITUTE($A27,"{U}",Q$16),SSC_Ontology_Ver0.5!$C$815:$C$1346,$B27,SSC_Ontology_Ver0.5!$D$815:$D$1346,SUBSTITUTE($C27,"{U}",Q$16)) -> 1 | R27: =IF($B27="rec:locatedIn","Excluded - location varies by unit",IF(AND(MIN(D27:Q27)=MAX(D27:Q27),MAX(D27:Q27)=1),"OK",IF(MIN(D27:Q27)=0,"Not on all units","Duplicated"))) -> OK
A28: entity:SSC_{U} | B28: brick:hasPoint | C28: entity:SSC_{U}_Fan_On_Status | D28: =COUNTIFS(SSC_Ontology_Ver0.5!$A$815:$A$1346,SUBSTITUTE($A28,"{U}",D$16),SSC_Ontology_Ver0.5!$C$815:$C$1346,$B28,SSC_Ontology_Ver0.5!$D$815:$D$1346,SUBSTITUTE($C28,"{U}",D$16)) -> 1 | E28: =COUNTIFS(SSC_Ontology_Ver0.5!$A$815:$A$1346,SUBSTITUTE($A28,"{U}",E$16),SSC_Ontology_Ver0.5!$C$815:$C$1346,$B28,SSC_Ontology_Ver0.5!$D$815:$D$1346,SUBSTITUTE($C28,"{U}",E$16)) -> 1 | F28: =COUNTIFS(SSC_Ontology_Ver0.5!$A$815:$A$1346,SUBSTITUTE($A28,"{U}",F$16),SSC_Ontology_Ver0.5!$C$815:$C$1346,$B28,SSC_Ontology_Ver0.5!$D$815:$D$1346,SUBSTITUTE($C28,"{U}",F$16)) -> 1 | G28: =COUNTIFS(SSC_Ontology_Ver0.5!$A$815:$A$1346,SUBSTITUTE($A28,"{U}",G$16),SSC_Ontology_Ver0.5!$C$815:$C$1346,$B28,SSC_Ontology_Ver0.5!$D$815:$D$1346,SUBSTITUTE($C28,"{U}",G$16)) -> 1 | H28: =COUNTIFS(SSC_Ontology_Ver0.5!$A$815:$A$1346,SUBSTITUTE($A28,"{U}",H$16),SSC_Ontology_Ver0.5!$C$815:$C$1346,$B28,SSC_Ontology_Ver0.5!$D$815:$D$1346,SUBSTITUTE($C28,"{U}",H$16)) -> 1 | I28: =COUNTIFS(SSC_Ontology_Ver0.5!$A$815:$A$1346,SUBSTITUTE($A28,"{U}",I$16),SSC_Ontology_Ver0.5!$C$815:$C$1346,$B28,SSC_Ontology_Ver0.5!$D$815:$D$1346,SUBSTITUTE($C28,"{U}",I$16)) -> 1 | J28: =COUNTIFS(SSC_Ontology_Ver0.5!$A$815:$A$1346,SUBSTITUTE($A28,"{U}",J$16),SSC_Ontology_Ver0.5!$C$815:$C$1346,$B28,SSC_Ontology_Ver0.5!$D$815:$D$1346,SUBSTITUTE($C28,"{U}",J$16)) -> 1 | K28: =COUNTIFS(SSC_Ontology_Ver0.5!$A$815:$A$1346,SUBSTITUTE($A28,"{U}",K$16),SSC_Ontology_Ver0.5!$C$815:$C$1346,$B28,SSC_Ontology_Ver0.5!$D$815:$D$1346,SUBSTITUTE($C28,"{U}",K$16)) -> 1 | ... Q28: =COUNTIFS(SSC_Ontology_Ver0.5!$A$815:$A$1346,SUBSTITUTE($A28,"{U}",Q$16),SSC_Ontology_Ver0.5!$C$815:$C$1346,$B28,SSC_Ontology_Ver0.5!$D$815:$D$1346,SUBSTITUTE($C28,"{U}",Q$16)) -> 1 | R28: =IF($B28="rec:locatedIn","Excluded - location varies by unit",IF(AND(MIN(D28:Q28)=MAX(D28:Q28),MAX(D28:Q28)=1),"OK",IF(MIN(D28:Q28)=0,"Not on all units","Duplicated"))) -> OK
... A56: entity:SSC_{U} | B56: rec:locatedIn | C56: entity:SSC_B1_017_MDF-2 | D56: =COUNTIFS(SSC_Ontology_Ver0.5!$A$815:$A$1346,SUBSTITUTE($A56,"{U}",D$16),SSC_Ontology_Ver0.5!$C$815:$C$1346,$B56,SSC_Ontology_Ver0.5!$D$815:$D$1346,SUBSTITUTE($C56,"{U}",D$16)) -> 0 | E56: =COUNTIFS(SSC_Ontology_Ver0.5!$A$815:$A$1346,SUBSTITUTE($A56,"{U}",E$16),SSC_Ontology_Ver0.5!$C$815:$C$1346,$B56,SSC_Ontology_Ver0.5!$D$815:$D$1346,SUBSTITUTE($C56,"{U}",E$16)) -> 0 | F56: =COUNTIFS(SSC_Ontology_Ver0.5!$A$815:$A$1346,SUBSTITUTE($A56,"{U}",F$16),SSC_Ontology_Ver0.5!$C$815:$C$1346,$B56,SSC_Ontology_Ver0.5!$D$815:$D$1346,SUBSTITUTE($C56,"{U}",F$16)) -> 0 | G56: =COUNTIFS(SSC_Ontology_Ver0.5!$A$815:$A$1346,SUBSTITUTE($A56,"{U}",G$16),SSC_Ontology_Ver0.5!$C$815:$C$1346,$B56,SSC_Ontology_Ver0.5!$D$815:$D$1346,SUBSTITUTE($C56,"{U}",G$16)) -> 0 | H56: =COUNTIFS(SSC_Ontology_Ver0.5!$A$815:$A$1346,SUBSTITUTE($A56,"{U}",H$16),SSC_Ontology_Ver0.5!$C$815:$C$1346,$B56,SSC_Ontology_Ver0.5!$D$815:$D$1346,SUBSTITUTE($C56,"{U}",H$16)) -> 0 | I56: =COUNTIFS(SSC_Ontology_Ver0.5!$A$815:$A$1346,SUBSTITUTE($A56,"{U}",I$16),SSC_Ontology_Ver0.5!$C$815:$C$1346,$B56,SSC_Ontology_Ver0.5!$D$815:$D$1346,SUBSTITUTE($C56,"{U}",I$16)) -> 0 | J56: =COUNTIFS(SSC_Ontology_Ver0.5!$A$815:$A$1346,SUBSTITUTE($A56,"{U}",J$16),SSC_Ontology_Ver0.5!$C$815:$C$1346,$B56,SSC_Ontology_Ver0.5!$D$815:$D$1346,SUBSTITUTE($C56,"{U}",J$16)) -> 0 | K56: =COUNTIFS(SSC_Ontology_Ver0.5!$A$815:$A$1346,SUBSTITUTE($A56,"{U}",K$16),SSC_Ontology_Ver0.5!$C$815:$C$1346,$B56,SSC_Ontology_Ver0.5!$D$815:$D$1346,SUBSTITUTE($C56,"{U}",K$16)) -> 0 | ... Q56: =COUNTIFS(SSC_Ontology_Ver0.5!$A$815:$A$1346,SUBSTITUTE($A56,"{U}",Q$16),SSC_Ontology_Ver0.5!$C$815:$C$1346,$B56,SSC_Ontology_Ver0.5!$D$815:$D$1346,SUBSTITUTE($C56,"{U}",Q$16)) -> 1 | R56: =IF($B56="rec:locatedIn","Excluded - location varies by unit",IF(AND(MIN(D56:Q56)=MAX(D56:Q56),MAX(D56:Q56)=1),"OK",IF(MIN(D56:Q56)=0,"Not on all units","Duplicated"))) -> Excluded - location varies by unit
A59: 4. Location breakdown — rec:locatedIn triple per unit
A60: Unit | B60: # of rec:locatedIn triples | C60: Room (object of the triple) | D60: Units sharing that room
A61: CCU3F0301 | B61: =COUNTIFS(SSC_Ontology_Ver0.5!$A$815:$A$1346,"entity:SSC_"&$A61,SSC_Ontology_Ver0.5!$C$815:$C$1346,"rec:locatedIn") -> 1 | C61: {=_xlfn.TEXTJOIN(" ; ",TRUE,IF((SSC_Ontology_Ver0.5!$A$815:$A$1346="entity:SSC_"&$A61)*(SSC_Ontology_Ver0.5!$C$815:$C$1346="rec:locatedIn"),SSC_Ontology_Ver0.5!$D$815:$D$1346,""))} -> entity:SSC_B1_038_SER-2 | D61: =COUNTIFS(SSC_Ontology_Ver0.5!$C$815:$C$1346,"rec:locatedIn",SSC_Ontology_Ver0.5!$D$815:$D$1346,$C61) -> 6
A62: CCU3F0302 | B62: =COUNTIFS(SSC_Ontology_Ver0.5!$A$815:$A$1346,"entity:SSC_"&$A62,SSC_Ontology_Ver0.5!$C$815:$C$1346,"rec:locatedIn") -> 1 | C62: {=_xlfn.TEXTJOIN(" ; ",TRUE,IF((SSC_Ontology_Ver0.5!$A$815:$A$1346="entity:SSC_"&$A62)*(SSC_Ontology_Ver0.5!$C$815:$C$1346="rec:locatedIn"),SSC_Ontology_Ver0.5!$D$815:$D$1346,""))} -> entity:SSC_B1_038_SER-2 | D62: =COUNTIFS(SSC_Ontology_Ver0.5!$C$815:$C$1346,"rec:locatedIn",SSC_Ontology_Ver0.5!$D$815:$D$1346,$C62) -> 6
A63: CCUB0001A | B63: =COUNTIFS(SSC_Ontology_Ver0.5!$A$815:$A$1346,"entity:SSC_"&$A63,SSC_Ontology_Ver0.5!$C$815:$C$1346,"rec:locatedIn") -> 1 | C63: {=_xlfn.TEXTJOIN(" ; ",TRUE,IF((SSC_Ontology_Ver0.5!$A$815:$A$1346="entity:SSC_"&$A63)*(SSC_Ontology_Ver0.5!$C$815:$C$1346="rec:locatedIn"),SSC_Ontology_Ver0.5!$D$815:$D$1346,""))} -> entity:SSC_B1_038_SER-2 | D63: =COUNTIFS(SSC_Ontology_Ver0.5!$C$815:$C$1346,"rec:locatedIn",SSC_Ontology_Ver0.5!$D$815:$D$1346,$C63) -> 6
A64: CCUB0001B | B64: =COUNTIFS(SSC_Ontology_Ver0.5!$A$815:$A$1346,"entity:SSC_"&$A64,SSC_Ontology_Ver0.5!$C$815:$C$1346,"rec:locatedIn") -> 1 | C64: {=_xlfn.TEXTJOIN(" ; ",TRUE,IF((SSC_Ontology_Ver0.5!$A$815:$A$1346="entity:SSC_"&$A64)*(SSC_Ontology_Ver0.5!$C$815:$C$1346="rec:locatedIn"),SSC_Ontology_Ver0.5!$D$815:$D$1346,""))} -> entity:SSC_B1_038_SER-2 | D64: =COUNTIFS(SSC_Ontology_Ver0.5!$C$815:$C$1346,"rec:locatedIn",SSC_Ontology_Ver0.5!$D$815:$D$1346,$C64) -> 6
A65: CCUB0002A | B65: =COUNTIFS(SSC_Ontology_Ver0.5!$A$815:$A$1346,"entity:SSC_"&$A65,SSC_Ontology_Ver0.5!$C$815:$C$1346,"rec:locatedIn") -> 1 | C65: {=_xlfn.TEXTJOIN(" ; ",TRUE,IF((SSC_Ontology_Ver0.5!$A$815:$A$1346="entity:SSC_"&$A65)*(SSC_Ontology_Ver0.5!$C$815:$C$1346="rec:locatedIn"),SSC_Ontology_Ver0.5!$D$815:$D$1346,""))} -> entity:SSC_B1_038_SER-2 | D65: =COUNTIFS(SSC_Ontology_Ver0.5!$C$815:$C$1346,"rec:locatedIn",SSC_Ontology_Ver0.5!$D$815:$D$1346,$C65) -> 6
A66: CCUB0002B | B66: =COUNTIFS(SSC_Ontology_Ver0.5!$A$815:$A$1346,"entity:SSC_"&$A66,SSC_Ontology_Ver0.5!$C$815:$C$1346,"rec:locatedIn") -> 1 | C66: {=_xlfn.TEXTJOIN(" ; ",TRUE,IF((SSC_Ontology_Ver0.5!$A$815:$A$1346="entity:SSC_"&$A66)*(SSC_Ontology_Ver0.5!$C$815:$C$1346="rec:locatedIn"),SSC_Ontology_Ver0.5!$D$815:$D$1346,""))} -> entity:SSC_B1_038_SER-2 | D66: =COUNTIFS(SSC_Ontology_Ver0.5!$C$815:$C$1346,"rec:locatedIn",SSC_Ontology_Ver0.5!$D$815:$D$1346,$C66) -> 6
A67: CCUB0003 | B67: =COUNTIFS(SSC_Ontology_Ver0.5!$A$815:$A$1346,"entity:SSC_"&$A67,SSC_Ontology_Ver0.5!$C$815:$C$1346,"rec:locatedIn") -> 1 | C67: {=_xlfn.TEXTJOIN(" ; ",TRUE,IF((SSC_Ontology_Ver0.5!$A$815:$A$1346="entity:SSC_"&$A67)*(SSC_Ontology_Ver0.5!$C$815:$C$1346="rec:locatedIn"),SSC_Ontology_Ver0.5!$D$815:$D$1346,""))} -> entity:SSC_B1_023_Q_TEL | D67: =COUNTIFS(SSC_Ontology_Ver0.5!$C$815:$C$1346,"rec:locatedIn",SSC_Ontology_Ver0.5!$D$815:$D$1346,$C67) -> 6
A68: CCUB0004 | B68: =COUNTIFS(SSC_Ontology_Ver0.5!$A$815:$A$1346,"entity:SSC_"&$A68,SSC_Ontology_Ver0.5!$C$815:$C$1346,"rec:locatedIn") -> 1 | C68: {=_xlfn.TEXTJOIN(" ; ",TRUE,IF((SSC_Ontology_Ver0.5!$A$815:$A$1346="entity:SSC_"&$A68)*(SSC_Ontology_Ver0.5!$C$815:$C$1346="rec:locatedIn"),SSC_Ontology_Ver0.5!$D$815:$D$1346,""))} -> entity:SSC_B1_023_Q_TEL | D68: =COUNTIFS(SSC_Ontology_Ver0.5!$C$815:$C$1346,"rec:locatedIn",SSC_Ontology_Ver0.5!$D$815:$D$1346,$C68) -> 6
A69: CCUB0005A | B69: =COUNTIFS(SSC_Ontology_Ver0.5!$A$815:$A$1346,"entity:SSC_"&$A69,SSC_Ontology_Ver0.5!$C$815:$C$1346,"rec:locatedIn") -> 1 | C69: {=_xlfn.TEXTJOIN(" ; ",TRUE,IF((SSC_Ontology_Ver0.5!$A$815:$A$1346="entity:SSC_"&$A69)*(SSC_Ontology_Ver0.5!$C$815:$C$1346="rec:locatedIn"),SSC_Ontology_Ver0.5!$D$815:$D$1346,""))} -> entity:SSC_B1_023_Q_TEL | D69: =COUNTIFS(SSC_Ontology_Ver0.5!$C$815:$C$1346,"rec:locatedIn",SSC_Ontology_Ver0.5!$D$815:$D$1346,$C69) -> 6
A70: CCUB0005B | B70: =COUNTIFS(SSC_Ontology_Ver0.5!$A$815:$A$1346,"entity:SSC_"&$A70,SSC_Ontology_Ver0.5!$C$815:$C$1346,"rec:locatedIn") -> 1 | C70: {=_xlfn.TEXTJOIN(" ; ",TRUE,IF((SSC_Ontology_Ver0.5!$A$815:$A$1346="entity:SSC_"&$A70)*(SSC_Ontology_Ver0.5!$C$815:$C$1346="rec:locatedIn"),SSC_Ontology_Ver0.5!$D$815:$D$1346,""))} -> entity:SSC_B1_023_Q_TEL | D70: =COUNTIFS(SSC_Ontology_Ver0.5!$C$815:$C$1346,"rec:locatedIn",SSC_Ontology_Ver0.5!$D$815:$D$1346,$C70) -> 6
A71: CCUB0006A | B71: =COUNTIFS(SSC_Ontology_Ver0.5!$A$815:$A$1346,"entity:SSC_"&$A71,SSC_Ontology_Ver0.5!$C$815:$C$1346,"rec:locatedIn") -> 1 | C71: {=_xlfn.TEXTJOIN(" ; ",TRUE,IF((SSC_Ontology_Ver0.5!$A$815:$A$1346="entity:SSC_"&$A71)*(SSC_Ontology_Ver0.5!$C$815:$C$1346="rec:locatedIn"),SSC_Ontology_Ver0.5!$D$815:$D$1346,""))} -> entity:SSC_B1_023_Q_TEL | D71: =COUNTIFS(SSC_Ontology_Ver0.5!$C$815:$C$1346,"rec:locatedIn",SSC_Ontology_Ver0.5!$D$815:$D$1346,$C71) -> 6
A72: CCUB0006B | B72: =COUNTIFS(SSC_Ontology_Ver0.5!$A$815:$A$1346,"entity:SSC_"&$A72,SSC_Ontology_Ver0.5!$C$815:$C$1346,"rec:locatedIn") -> 1 | C72: {=_xlfn.TEXTJOIN(" ; ",TRUE,IF((SSC_Ontology_Ver0.5!$A$815:$A$1346="entity:SSC_"&$A72)*(SSC_Ontology_Ver0.5!$C$815:$C$1346="rec:locatedIn"),SSC_Ontology_Ver0.5!$D$815:$D$1346,""))} -> entity:SSC_B1_023_Q_TEL | D72: =COUNTIFS(SSC_Ontology_Ver0.5!$C$815:$C$1346,"rec:locatedIn",SSC_Ontology_Ver0.5!$D$815:$D$1346,$C72) -> 6
...

Sheet AHU_Comparison
A1: AHU Ontology Consistency Check — SSC_AHUB0001 to SSC_AHUB0005
A2: Source: SSC_Ontology_Ver0.5!A128:D773 (646 triples). Relations normalised by replacing the AHU id with {N}, then counted per unit. rec:locatedIn relations are excluded - location legitimately differs by unit.
A4: 1. Triple count per AHU
A5: Metric | B5: AHUB0001 | C5: AHUB0002 | D5: AHUB0003 | E5: AHUB0004 | F5: AHUB0005
A6: Rows in source | B6: =COUNTIF(SSC_Ontology_Ver0.5!$A$128:$A$773,"*AHUB0001*") -> 129 | C6: =COUNTIF(SSC_Ontology_Ver0.5!$A$128:$A$773,"*AHUB0002*") -> 130 | D6: =COUNTIF(SSC_Ontology_Ver0.5!$A$128:$A$773,"*AHUB0003*") -> 128 | E6: =COUNTIF(SSC_Ontology_Ver0.5!$A$128:$A$773,"*AHUB0004*") -> 132 | F6: =COUNTIF(SSC_Ontology_Ver0.5!$A$128:$A$773,"*AHUB0005*") -> 127
A7: Difference vs AHUB0001 | B7: =0 -> 0 | C7: =C6-$B$6 -> 1 | D7: =D6-$B$6 -> -1 | E7: =E6-$B$6 -> 3 | F7: =F6-$B$6 -> -2
A9: 2. Discrepancies (relations whose count is not identical across the 5 AHUs — location relations excluded)
A10: Subject pattern | B10: Predicate | C10: Object pattern | D10: AHUB0001 | E10: AHUB0002 | F10: AHUB0003 | G10: AHUB0004 | H10: AHUB0005 | I10: Finding
A11: entity:SSC_AHUB{N} | B11: brick:hasPoint | C11: entity:SSC_AHUB{N}_SAP_Setpoint | D11: =COUNTIFS(SSC_Ontology_Ver0.5!$A$128:$A$773,SUBSTITUTE($A11,"AHUB{N}",D$10),SSC_Ontology_Ver0.5!$C$128:$C$773,$B11,SSC_Ontology_Ver0.5!$D$128:$D$773,SUBSTITUTE($C11,"AHUB{N}",D$10)) -> 1 | E11: =COUNTIFS(SSC_Ontology_Ver0.5!$A$128:$A$773,SUBSTITUTE($A11,"AHUB{N}",E$10),SSC_Ontology_Ver0.5!$C$128:$C$773,$B11,SSC_Ontology_Ver0.5!$D$128:$D$773,SUBSTITUTE($C11,"AHUB{N}",E$10)) -> 1 | F11: =COUNTIFS(SSC_Ontology_Ver0.5!$A$128:$A$773,SUBSTITUTE($A11,"AHUB{N}",F$10),SSC_Ontology_Ver0.5!$C$128:$C$773,$B11,SSC_Ontology_Ver0.5!$D$128:$D$773,SUBSTITUTE($C11,"AHUB{N}",F$10)) -> 0 | G11: =COUNTIFS(SSC_Ontology_Ver0.5!$A$128:$A$773,SUBSTITUTE($A11,"AHUB{N}",G$10),SSC_Ontology_Ver0.5!$C$128:$C$773,$B11,SSC_Ontology_Ver0.5!$D$128:$D$773,SUBSTITUTE($C11,"AHUB{N}",G$10)) -> 1 | H11: =COUNTIFS(SSC_Ontology_Ver0.5!$A$128:$A$773,SUBSTITUTE($A11,"AHUB{N}",H$10),SSC_Ontology_Ver0.5!$C$128:$C$773,$B11,SSC_Ontology_Ver0.5!$D$128:$D$773,SUBSTITUTE($C11,"AHUB{N}",H$10)) -> 0 | I11: MISSING: SAP_Setpoint point not declared on AHUB0003 and AHUB0005 | J11: Missing or doesn’t exist?
A12: entity:SSC_AHUB{N}_SAP_Setpoint | B12: ref:hasExternalReference | C12: <blanknode> | D12: =COUNTIFS(SSC_Ontology_Ver0.5!$A$128:$A$773,SUBSTITUTE($A12,"AHUB{N}",D$10),SSC_Ontology_Ver0.5!$C$128:$C$773,$B12,SSC_Ontology_Ver0.5!$D$128:$D$773,SUBSTITUTE($C12,"AHUB{N}",D$10)) -> 1 | E12: =COUNTIFS(SSC_Ontology_Ver0.5!$A$128:$A$773,SUBSTITUTE($A12,"AHUB{N}",E$10),SSC_Ontology_Ver0.5!$C$128:$C$773,$B12,SSC_Ontology_Ver0.5!$D$128:$D$773,SUBSTITUTE($C12,"AHUB{N}",E$10)) -> 1 | F12: =COUNTIFS(SSC_Ontology_Ver0.5!$A$128:$A$773,SUBSTITUTE($A12,"AHUB{N}",F$10),SSC_Ontology_Ver0.5!$C$128:$C$773,$B12,SSC_Ontology_Ver0.5!$D$128:$D$773,SUBSTITUTE($C12,"AHUB{N}",F$10)) -> 0 | G12: =COUNTIFS(SSC_Ontology_Ver0.5!$A$128:$A$773,SUBSTITUTE($A12,"AHUB{N}",G$10),SSC_Ontology_Ver0.5!$C$128:$C$773,$B12,SSC_Ontology_Ver0.5!$D$128:$D$773,SUBSTITUTE($C12,"AHUB{N}",G$10)) -> 1 | H12: =COUNTIFS(SSC_Ontology_Ver0.5!$A$128:$A$773,SUBSTITUTE($A12,"AHUB{N}",H$10),SSC_Ontology_Ver0.5!$C$128:$C$773,$B12,SSC_Ontology_Ver0.5!$D$128:$D$773,SUBSTITUTE($C12,"AHUB{N}",H$10)) -> 0 | I12: MISSING: no external reference for SAP_Setpoint on AHUB0003 and AHUB0005 (entity absent) | J12: based on above
A13: entity:SSC_AHUB{N}_RF | B13: brick:hasPoint | C13: entity:SSC_AHUB{N}_RF_AutoMan_Status | D13: =COUNTIFS(SSC_Ontology_Ver0.5!$A$128:$A$773,SUBSTITUTE($A13,"AHUB{N}",D$10),SSC_Ontology_Ver0.5!$C$128:$C$773,$B13,SSC_Ontology_Ver0.5!$D$128:$D$773,SUBSTITUTE($C13,"AHUB{N}",D$10)) -> 1 | E13: =COUNTIFS(SSC_Ontology_Ver0.5!$A$128:$A$773,SUBSTITUTE($A13,"AHUB{N}",E$10),SSC_Ontology_Ver0.5!$C$128:$C$773,$B13,SSC_Ontology_Ver0.5!$D$128:$D$773,SUBSTITUTE($C13,"AHUB{N}",E$10)) -> 1 | F13: =COUNTIFS(SSC_Ontology_Ver0.5!$A$128:$A$773,SUBSTITUTE($A13,"AHUB{N}",F$10),SSC_Ontology_Ver0.5!$C$128:$C$773,$B13,SSC_Ontology_Ver0.5!$D$128:$D$773,SUBSTITUTE($C13,"AHUB{N}",F$10)) -> 1 | G13: =COUNTIFS(SSC_Ontology_Ver0.5!$A$128:$A$773,SUBSTITUTE($A13,"AHUB{N}",G$10),SSC_Ontology_Ver0.5!$C$128:$C$773,$B13,SSC_Ontology_Ver0.5!$D$128:$D$773,SUBSTITUTE($C13,"AHUB{N}",G$10)) -> 0 | H13: =COUNTIFS(SSC_Ontology_Ver0.5!$A$128:$A$773,SUBSTITUTE($A13,"AHUB{N}",H$10),SSC_Ontology_Ver0.5!$C$128:$C$773,$B13,SSC_Ontology_Ver0.5!$D$128:$D$773,SUBSTITUTE($C13,"AHUB{N}",H$10)) -> 1 | I13: MISSING: Return Fan Auto/Manual status not declared on AHUB0004 | J13: Missing or doesn’t exist?
A14: entity:SSC_AHUB{N}_RF_AutoMan_Status | B14: ref:hasExternalReference | C14: <blanknode> | D14: =COUNTIFS(SSC_Ontology_Ver0.5!$A$128:$A$773,SUBSTITUTE($A14,"AHUB{N}",D$10),SSC_Ontology_Ver0.5!$C$128:$C$773,$B14,SSC_Ontology_Ver0.5!$D$128:$D$773,SUBSTITUTE($C14,"AHUB{N}",D$10)) -> 1 | E14: =COUNTIFS(SSC_Ontology_Ver0.5!$A$128:$A$773,SUBSTITUTE($A14,"AHUB{N}",E$10),SSC_Ontology_Ver0.5!$C$128:$C$773,$B14,SSC_Ontology_Ver0.5!$D$128:$D$773,SUBSTITUTE($C14,"AHUB{N}",E$10)) -> 1 | F14: =COUNTIFS(SSC_Ontology_Ver0.5!$A$128:$A$773,SUBSTITUTE($A14,"AHUB{N}",F$10),SSC_Ontology_Ver0.5!$C$128:$C$773,$B14,SSC_Ontology_Ver0.5!$D$128:$D$773,SUBSTITUTE($C14,"AHUB{N}",F$10)) -> 1 | G14: =COUNTIFS(SSC_Ontology_Ver0.5!$A$128:$A$773,SUBSTITUTE($A14,"AHUB{N}",G$10),SSC_Ontology_Ver0.5!$C$128:$C$773,$B14,SSC_Ontology_Ver0.5!$D$128:$D$773,SUBSTITUTE($C14,"AHUB{N}",G$10)) -> 0 | H14: =COUNTIFS(SSC_Ontology_Ver0.5!$A$128:$A$773,SUBSTITUTE($A14,"AHUB{N}",H$10),SSC_Ontology_Ver0.5!$C$128:$C$773,$B14,SSC_Ontology_Ver0.5!$D$128:$D$773,SUBSTITUTE($C14,"AHUB{N}",H$10)) -> 1 | I14: MISSING: no external reference for RF_AutoMan_Status on AHUB0004 (entity absent) | J14: based on above
