Workbook

Sheet Claude Log
A1: Turn # | B1: Date | C1: User Request | D1: Action Taken | E1: Details | F1: Outcome
A2: 1 | B2: 46244 | C2: Provided full transcript from previous session (classifying HQ VAV/FCU tags as Included/Not Included in column D by room type across Ground Floor–Level 11). New session; selection at D1174. | D2: Loaded prior context; set up Claude Log sheet; inspected the registry section around D1174. | E2: Row 1170 = AHUB_0005; FCU numbering restarts at FCU0001 on row 1171 — this is a separate building/section where column D holds room descriptions (e.g. 'SPRINKLER AND WATER','B.M.S'), not Included/Not Included marks. AHUs (rows 4-28) still unmarked pending direction. | F2: Awaiting user direction on next step (new floor, AHU handling, or final excluded-room verification).
A3: 3 | B3: 46244 | C3: Clarified: wants room names (rooms served by each equipment tag) filled for the HQ block, rows 3–763, in column E (keeping the Included/Not Included marks in column D). | D3: Confirmed target column E via question; checked E is empty apart from a legend at E3/E4. Explained I cannot view the previous session's drawing images and my prior notes are not a clean per-row room map. | E3: Room names must be exact; prior notes grouped multiple tags per room label. Requested the floor drawings be resent one at a time to fill column E accurately, floor by floor. | F3: Awaiting user to resend the first HQ floor drawing to begin populating column E.
A4: 4 | B4: 46244 | C4: Said they will send the floor drawings later tonight. | D4: Acknowledged; no workbook changes made. Confirmed the floor-by-floor workflow to populate column E with room names once drawings arrive. | E4: No cells written to Controllable Asset Registry this turn. | F4: On hold — awaiting HQ floor drawings from user (expected tonight).
A5: 5 | B5: 46244 | C5: Sent HQ Roof Top (Level 12) drawing; asked me to start filling room names in column E for that floor. | D5: Wrote FCU room names to E155:E160 (FCU0126/0127 → 12.002 MCC Closet; FCU0128/0129 → 12.003 MCC Closet; FCU0130 → 12.004 MCC Closet; FCU0131 → roof plant/walkway near CSRR-0008). Verified by re-reading A155:E160. | E5: Roof VAV/12/01-13 units are NOT in the tag list (all VAV0001-0607 already assigned to Ground-L11; HQ block ends row 763, QNL starts 764). AHU/12/01-10 (rows 4-12) left blank — parked per earlier decision and AHUs don't serve a single room. | F5: Level 12 FCUs done. Flagged: SE 12.001 Electrical Closet sits beside 12.002 MCC Closet — could not confirm if one FCU serves 12.001 instead; FCU0131 has no room number on the drawing.
A6: 6 | B6: 46245 | C6: Sent the 3rd image pair — new: South Building L0 Section A1.3; old: North Building L0 Section A2.3. Asked me to continue the established workflow (map the new floor, extract standalone tags from the old floor). | D6: Filled 3 blank FCU rows (FCU6987 row 2118, SB FCU0001 row 2159, SB FCU2001 row 2168). Appended 33 new rows (2365-2397): 5 A1.3 South Building AT tags, 24 A2.3 North Building AT tags, 4 A2.3 standalone EV valves. Flagged 7 uncertain rows yellow in C:D. | E6: Duplicate avoidance: skipped AT-0006 (already row 2262 from B1.1) and all A2.3 numbers already embedded in existing VAV rows (5000/5002, 5001/5003, 5010/5011, 5015/5016, 5030/5031, 5040/5041, 5045/5046, 5395, 5400, 5405, 5410/5411, 6000/6001, 6010/6011, 6025/6026, 6240/6241, 6300, 6305, 6310, 6315/6316). Appended only valves with no VAV row: EV-5021, EV-5035, EV-6016, EV-6127. Equipment type = each tag's own prefix (AT/EV) per the standing rule. NB FCU5982/5991/5992/6985/6986 were already populated from an earlier session and matched A2.3, so left untouched. | F6: 3rd pair complete and verified (rows 2118, 2159, 2168, 2365-2397 re-read; no gaps). Next append row = 2398. Flagged yellow: AT-0002, AT-0005, AT-2001, AT-5030, AT-5045, EV-5035, EV-6127. Open note: A2.3 right-hand area is labelled RECEPTION AREA N-0169, which duplicates the left-side EXP. OFFICE N-0169 label - no tag sits there so no row was written.
A7: 7 | B7: 46245 | C7: Sent the 4th image pair — new: South Building L0 Section A1.2; old: North Building L0 Section B2.1. Continue the established workflow. | D7: Filled SB FCU2002-2005 (rows 2169-2172). Mapped 45 of 46 blank VAV rows for A1.2 (C/D 1738:1783 = VAV2002-VAV2047). Appended 112 rows (2398-2509): 45 A1.2 AT-20xx, 8 A1.2 standalone 0-series AT, 43 B2.1 AT, 15 B2.1 valves, FCU6997. Corrected AT-2001 (row 2369). Flagged 39 uncertain rows yellow, then fixed 14 misplaced flags. | E7: A1.2 turned out to be a map-the-rooms floor: VAV2002-VAV2047 existed but were blank, and AT numbers correspond 1:1 to VAV numbers. There is no VAV2001 row and no VAV rows for the 0115-0124 series, so those 9 tags were appended only. VAV2005 (row 1741) left blank - AT-2005 does not appear on A1.2. Self-caught error: skipping AT-2005 in the append shifted my flag row offsets by one, so 7 flags landed on confident rows (AT-2010/2014/2017/2018/2026/2034/2036) and 7 uncertain rows were unflagged; cleared and re-applied correctly. AT-2001 moved from Vestibule S-0202 (per A1.3) to High-Density Room S-0206 (per A1.2, box sits inside the room outline) - still flagged. | F7: 4th pair complete and verified (rows 2169-2172, 2369, 1738-1783, 2398-2510 re-read; no gaps; flag colours confirmed on C:D). Next append row = 2510. DEFERRED / NEEDS USER DECISION: (1) 21 blank NB VAV rows discovered - 1468 (VAV6295), 1473-1490 (VAV6320-6410), 1543-1544 (VAV7385/7390) - not filled because two existing rows conflict with the drawing, so a bulk same-number fill is unsafe. (2) Conflict A: registry row 1465 VAV6220 = Conf N-0331 and row 1463 VAV6205 = Emergency Elec. N-0333, but B2.1 shows AT-6220 at Emergency Elec. N-0333 and AT-6205 at Conference N-0331 (appears swapped). (3) Conflict B: registry row 1485 VAV6380 = Office N-0376, but B2.1 shows AT-6370 at Office N-0376 and AT-6380 at Workstation N-0378 (possible off-by-one, same pattern as the A2.2 fix).
A8: 8 | B8: 46245 | C8: Sent the 5th image pair — new: South Building L0 Section A1.1; old: North Building L0 Section B2.2. Continue the established workflow. | D8: A1.1: filled VAV3001-3007 (rows 1784-1790) and FCU3001 (row 2173); appended 45 tags (2510-2554) = 32 AT-30xx plus 13 of the 2301-AT-01xx BACnet points. B2.2: appended 77 rows (2555-2631) = 51 AT (incl. the AT-7090/7105/7120 multi-node sensors), 8 standalone EV, 17 lab valves, FCU7993. Flagged 34 rows yellow across both. | E8: B2.2's VAV rows mostly already existed with rooms, so the AT twins inherited the registry room (consistent with the A2.1/A2.2 approach) rather than my read of the drawing; the five places where the drawing disagrees were flagged instead of overwritten. Multi-node tags (AT-7090-N1/N2, AT-7105-N1/N2, AT-7120-N1..N9) have no VAV rows and were mapped from the drawing to N-0412/0412A, N-0415/0415A, N-0418/0418A and N-0430A..N-0430F - all flagged. Skipped every valve already embedded in a VAV row name (VEV7031, VEV7051, VEV7061, CEV7221, VEV7231, VEV7241A, VEV7251/7261/7271/7281/7291/7311/7321/7331/7341/7351/7361/7371, EV7126/7141/7186/7216/7495). FEV-7232 appears twice on the drawing - appended once and flagged. | F8: 5th pair complete and verified (rows 1784-1790, 2173, 2510-2632 re-read; 122 appended rows with no gaps; flag colours spot-checked against tag names). Next append row = 2632. NEW CONFLICTS FLAGGED, NOT OVERWRITTEN: (1) FCU rows 2119/2120/2121 (FCU7981 = Stair 5 N-0STO5, FCU7982 and FCU7983 = Service Corridor N-0344) disagree with B2.2, which shows FCU-7993 at Stair 5, FCU-7981 at IDF N-0419 and FCU-7982 near Mech/FPC N-0434. (2) Row 2085 FCU7790 is tagged NB_1F but B2.2 (Level 0) shows FCU-7790 at Stair 6 N-0ST06. (3) Registry rows 1517/1518 give both VAV7145 and VAV7155 the same room (Office N-0427) - drawing suggests 7145 = N-0425. (4) Row 1519 VAV7165 = N-0428 vs drawing N-0429. (5) Row 1523 VAV7185 = Office N-0426 vs drawing Emer. Elec. Room N-0433, and row 1526 VAV7215 = Emergency Elec. N-0433 vs drawing Office N-0438. STILL OPEN from turn 7: the 21 blank NB VAV rows (1468, 1473-1490, 1543-1544) and the VAV6205/6220 and VAV6380 conflicts.
A9: 9 | B9: 46245 | C9: Sent the 6th image pair — new: South Building Level 1 Section B1.2; old: North Building Level 01 Section A2.1. First pair on Level 1 rather than Level 0. | D9: B1.2: filled 45 blank VAV rows (C/D across 1595:1645) and FCU1503 (row 2132); appended 49 AT tags (2632-2680). A2.1 L01: appended 28 rows (2681-2708) = 8 AT twins, 19 valves, FCU2004. Flagged 5 rows yellow after correcting 2 that landed one row off. | E9: Both drawings are Level 1, so writes went to the SB_1F and NB_1F blocks (not GF). SB VAV15xx occupies rows 1590-1645 but the series is not contiguous - VAV1504, 1535, 1537, 1538 and 1541 have no rows, so AT-1504/1535/1537 were appended only. NB_1F registry rooms for VAV4660-4745 matched my reading of the drawing exactly (N-1227 through N-1244), so those 8 AT twins needed no flags. NB_1F FCU4910/4915/4916/4917 were already correctly populated and match A2.1, so left untouched. Skipped valves already embedded in VAV row names (VEV4621, VEV4631, VEV4051/4061/4091, the VAV4070-4083 high-bay pairs) and VEV-4041 which was already appended at row 2253. | F9: 6th pair complete and verified (rows 1590-1645, 2132, 2632-2709 re-read; 77 appended rows with no gaps; flag cells checked against tag names). Next append row = 2709. Flagged: AT-1504 (corridor position), AT-1533 and AT-1536 (sit between an electrical room and an office), AT-1537, CEV-4502, FCU2004. Still-blank SB L1 VAV rows with no tag on this drawing: 1590-1594 (VAV1501-1503, 1505, 1506), 1624-1625 (VAV1539/1540), 1627-1629 (VAV1543-1545), 1631 (VAV1547) - likely on the B1.1 half of Level 1. STILL OPEN: the 21 blank NB GF VAV rows (1468, 1473-1490, 1543-1544) and the registry conflicts at rows 1463/1465, 1485, 1517/1518, 1519, 1523/1526, 2085, 2119-2121.
A10: 10 | B10: 46245 | C10: Sent the 7th image pair — new: South Building Level 1 Section B1.1; old: North Building Level 1 Section A2.2. | D10: B1.1: filled 34 blank VAV rows (1566-1594, 1624-1631) + FCU1501/1502 (2130-2131); appended 46 AT tags (2709-2754). A2.2: filled FCU5986 (2076) and VAV4650 (1842); appended 67 rows (2755-2821) = 42 AT, 7 EV, 18 lab valves. Flagged 12 rows yellow. | E10: ERROR MADE AND CORRECTED: I wrote to FCU5983 (row 2073) and FCU5984 (row 2074) without reading them first - they already held 'Not Included / JC N-1139' and 'Included / Corridor N-1138'. I overwrote both with my own reading of the drawing (IDF N-1140 / JC N-1139), then restored the original values from the pre-write snapshot and flagged all three rows instead. Only FCU5986 was genuinely blank and kept a new value. Lesson: read FCU rows before writing, as several were populated in earlier sessions. Otherwise: NB_1F VAV5650-5940 rooms already matched the drawing closely, so those 38 AT twins inherited the registry room. Skipped valves embedded in VAV row names (VEV5601/5611/5622/5623/5631/5771/5781/5793/5795A/5801, EV5656/5716/5731/5736/5741/5761/5836). Unnumbered 'TAG 0.0' boxes on A2.2 could not be appended. | F10: 7th pair complete and verified (rows 1566-1645, 1842, 2073-2076, 2130-2132, 2709-2822 re-read; 113 appended rows with no gaps; all 12 flag cells checked against tag names). Next append row = 2822. South Building Level 1 is now fully mapped except VAV0509 (row 1569) - no AT-0509 appears on either B1.1 or B1.2. Flagged: AT-0504, AT-0505, AT-0515, AT-0534, AT-0529, AT-5685 (registry calls N-1126 an Office, drawing calls it Corridor), AT-5840 and AT-5905 (registry gives both Office N-1163), EV-5686, VEV-5581 (label appears twice on drawing), VEV-5821, FCU1503 (row 2132 - B1.2 shows it at Stair 1, B1.1 shows it near FPC S-1108/UPS S-1107D), FCU5983/5984/5986. STILL OPEN: 21 blank NB GF VAV rows (1468, 1473-1490, 1543-1544) and conflicts at rows 1463/1465, 1485, 1517/1518, 1519, 1523/1526, 2085, 2119-2121.
A11: 11 | B11: 46245 | C11: Sent the 8th image pair — new: South Building Level 1 Section A1.3; old: North Building Level 1 Section A2.3. Both are sparse core/lobby sections. | D11: A1.3: filled VAV2501 (row 1646, Lobby S-1201), FCU0501 (2127, Stair 2 S-1ST02) and FCU2501 (2133, Stair 3 S-1ST03); appended 2 AT tags (2822-2823 = AT-2501 Lobby S-1201, AT-2507 Female S-1204); corrected AT-0503 and AT-0505 rooms. A2.3: NO rows written - see details. Flagged 4 rows. | E11: Pre-read all three fill targets before writing this turn (lesson from turn 10) - all were genuinely blank. AT-0503 changed from NCIR Office S-1115 to Women S-1106B and AT-0505 from UPS S-1107D to Emergency Elec. S-1107B: A1.3 is the section that actually contains the S-1105/S-1106B/S-1107B core, AT-0502 already matched Vestibule S-1105, and 0502/0503/0505 form a clean sequence onto those three rooms. A2.3 yielded nothing appendable: every sensor box on it is an unnumbered 'TAG' with no tag ID, so there is nothing to key a registry row on. Separately, FCU-2004 appears SIX times on A2.3 (Stair 3 N-1ST03, Stair 4 N-1ST04, Normal Elec. N-1310, IDF N-1311, Mech/FPC N-1353A, Reception N-1355) all reading 25.3 C - one BMS point bound to six graphic boxes, so no new rows could be derived; flagged row 2708 instead. | F11: 8th pair complete and verified (rows 1646, 2127, 2133, 2708, 2711-2713, 2822-2824 re-read; flag fills confirmed). Next append row = 2824. OPEN QUESTION raised: moving AT-0503 to Women S-1106B leaves NCIR Office S-1115 with no sensor and VAV0509 (row 1569) still blank - the B1.1 tag I read as AT-0503 in that office may actually be AT-0509. Needs user confirmation before writing. Flagged: AT-0503, AT-0505, AT-2501, FCU2004. STILL OPEN from earlier turns: 21 blank NB GF VAV rows (1468, 1473-1490, 1543-1544) and conflicts at rows 1463/1465, 1485, 1517/1518, 1519, 1523/1526, 2085, 2119-2121, 1889, 1910/1923, 2132, 2073/2074.
A12: 12 | B12: 46245 | C12: Sent the 9th image pair — new: South Building Level 1 Section A1.2; old: North Building Level 1 Section B2.1. | D12: A1.2: filled 50 blank VAV rows (C/D 1647:1696 = VAV2502-VAV2553) and 4 FCU rows (2134-2137); appended 51 AT tags (2824-2874). B2.1: appended 79 rows (2875-2953) = 40 AT, 8 EV, 31 lab valves. 130 appended rows total. Flagged 22 rows yellow. | E12: Pre-read all 54 fill targets before writing - all confirmed blank, no overwrite. Verified fill alignment by spot-checking VAV2511=Office S-1212, VAV2536=Normal Elec. S-1251, VAV2553=Male Prayer S-1278 after the block write. B2.1 registry rooms matched the drawing throughout (VAV6650-6725 = N-1319 to N-1336, VAV6900-6970 = N-1357 to N-1371, VAV7865 = N-1461A), so those 34 AT twins inherited the registry room with no flags. VAV6630B/6631B were checked and already populated (Bio-Med Chem Lab 1 N-1316L) so were skipped, as were FCU6988/6989 which already read Service Corridor N-1337 and match the drawing. Corridor-run valves EV-6936/6961/6969 were assigned by the EV-pairs-with-VAV convention (Workstation N-1363/N-1368/N-1371) and flagged, since the dotted corridor they sit on carries no room number on this drawing. | F12: 9th pair complete and verified (rows 1647-1696, 2080-2081, 2134-2137, 2824-2954 re-read; 130 appended rows with no gaps; all 22 flag cells checked against tag names). Next append row = 2954. Flagged: AT-2502/2503/2505/2506 and VAV2502/2503/2505/2506 (four lobby-band sensors with no room label of their own - all assigned Lobby S-1202), AT-2552/VAV2552 (label appears twice on A1.2), AT-4260 (4000-series tag on a South Building drawing, assigned Men S-1254), FCU2502-2505, AT-7500, EV-7501, EV-6936/6961/6969, CEV-6581, FEV-6731. STILL OPEN: 21 blank NB GF VAV rows (1468, 1473-1490, 1543-1544); conflicts at rows 1463/1465, 1485, 1517/1518, 1519, 1523/1526, 2085, 2119-2121, 1889, 1910/1923, 2132, 2073/2074; and the AT-0503/AT-0509 vs NCIR Office S-1115 question (row 1569 still blank).
A13: 13 | B13: 46245 | C13: Sent the 10th image pair — new: South Building Level 1 Section A1.1; old: North Building Level 1 Section B2.2. | D13: A1.1: filled 20 blank VAV rows (C/D 1697:1717 = VAV3504-VAV3524, leaving VAV3519 blank) and FCU3501 (row 2138, Stair S-1ST104); appended 28 AT tags (2954-2981). B2.2: appended 58 rows (2982-3039) = 42 AT, 8 EV, 8 lab valves. 86 appended rows total. Flagged 15 rows yellow. | E13: Pre-read all 22 fill targets and aborted-on-conflict guard was in the code; all were blank so nothing was overwritten. Verified alignment after the block write (VAV3504=Open Plan S-1229, VAV3514=Office S-1294, VAV3519 blank, VAV3524=Normal Elec. S-1238). VAV3519 left blank - no AT-3519 on the drawing. There are no VAV rows for AT-3501/3502/3503 or for the 2301-AT-02xx BACnet points, so those were appended only. B2.2 registry rooms matched the drawing throughout (VAV7620-7710 = N-1415 to N-1442, VAV7840-7960 = N-1458 to N-1480, and the N-1404x / N-1450x lab series), so all 42 AT twins inherited the registry room. RESOLVED an earlier flag: row 2085 FCU7790 was flagged in turn 8 because it carries the NB_1F tag but appeared on a Level 0 drawing - B2.2 (Level 1) now shows FCU-7790 at Stair 6 N-1ST06, matching the registry, so the NB_1F assignment looks correct and the Level 0 sighting was a graphic repeat. All seven NB_1F FCU rows (2085-2091) were already populated and match B2.2, so none were touched. | F13: 10th pair complete and verified (rows 1697-1717, 2085-2091, 2138, 2954-3040 re-read; 86 appended rows with no gaps; all 15 flag cells checked against tag names). Next append row = 3040. Flagged: AT-3501 (sits under Lobby S-0294 which is a Level 0 room number on a Level 1 drawing), AT-3502, AT-3511/VAV3511, AT-3514/VAV3514 and AT-3520/VAV3520 (drawing carries TWO rooms labelled OFFICE S-1294 - one bottom-centre, one right of the stair), AT-0207/AT-0208, AT-7705 (registry room is just 'Expansion (Office)' with no number), EV-7663, EV-7712, CEV-7761, CEV-7791. NEW pre-existing issue spotted: rows 2034 and 2036 both give Flow Cyto N-1450C (VEV7751 and VEV7781) but the drawing puts VEV-7781 in iPS-TC N-1450F. STILL OPEN: 21 blank NB GF VAV rows (1468, 1473-1490, 1543-1544); conflicts at rows 1463/1465, 1485, 1517/1518, 1519, 1523/1526, 2119-2121, 1889, 1910/1923, 2132, 2073/2074, 2034/2036; and the AT-0503/AT-0509 vs NCIR Office S-1115 question (row 1569 still blank).
... A59: 55 | B59: 46261 | C59: User asked to re-run the validation of the QNL room/equipment mapping. | D59: Re-audited 'Controllable Asset Registry' A779:A1329 against column D of 'QNL Room Names with Equip.'. Read-only; no changes made. | E59: Source range in the column D TRANSPOSE(FILTER(...)) formulas has widened since the earlier audit, from A779:A1229 to A779:A1329, and now carries an if_empty argument returning "No Equipment in entity". Rooms in column A run to row 353 (352 entities) with matching formulas in D2:D353. Audited against the widened range: 551 asset tags, 537 with a non-blank column E entity. Also checked CAR rows below 1329 - 271 further assets exist but all carry SSC_ prefixed entities (different building), so ending the range at 1329 is correct and no QNL assets are excluded. | F59: Clean. 537 of 537 eligible assets placed in the correct room row; 0 unplaced, 0 misplaced, 0 orphans, 0 spill errors, no duplicate tags or duplicate room entities. 14 blank-entity assets correctly excluded with no leakage. 154 rooms legitimately show "No Equipment in entity".

Sheet HQ Asset Register
A1: EQUIPMENT ASSET REGISTER
A2: Tag No. | B2: Equipment Type | C2: Description | D2: Remarks
A3: AHU12_0001 | B3: AHU | C3: Air Handling Unit
A4: AHU12_0002 | B4: AHU | C4: Air Handling Unit
A5: AHU12_0003 | B5: AHU | C5: Air Handling Unit
A6: AHU12_0004 | B6: AHU | C6: Air Handling Unit | F6: EQUIPMENT COUNT SUMMARY
A7: AHU12_0006 | B7: AHU | C7: Air Handling Unit | F7: AHU | G7: =COUNTIF(B:B,"AHU") -> 26
A8: AHU12_0007 | B8: AHU | C8: Air Handling Unit | F8: FCU | G8: =COUNTIF(B:B,"FCU") -> 133
A9: AHU12_0008 | B9: AHU | C9: Air Handling Unit | F9: CHW Pump | G9: =COUNTIF(B:B,"CHW Pump") -> 4
A10: AHU12_0009 | B10: AHU | C10: Air Handling Unit | F10: Variable Air Volume | G10: =COUNTIF(B:B,"VAV") -> 602
A11: AHU12_0010 | B11: AHU | C11: Air Handling Unit | F11: DX Unit | G11: =COUNTIF(B:B,"DX Unit") -> 24
A12: AHU2_0001 | B12: AHU | C12: Air Handling Unit | F12: Heat Exchanger | G12: =COUNTIF(B:B,"HEX") -> 5
A13: AHU5_0001 | B13: AHU | C13: Air Handling Unit | F13: CCU | G13: =COUNTIF(B:B,"CCU") -> 11
A14: AHU5_0002 | B14: AHU | C14: Air Handling Unit | F14: EF | G14: =COUNTIF(B:B,"EF") -> 12
A15: AHU9_0001 | B15: AHU | C15: Air Handling Unit | F15: GEF | G15: =COUNTIF(B:B,"GEF") -> 13
A16: AHU9_0002 | B16: AHU | C16: Air Handling Unit | F16: TEF | G16: =COUNTIF(B:B,"TEF") -> 4
A17: AHU9_0003 | B17: AHU | C17: Air Handling Unit | F17: CEF | G17: =COUNTIF(B:B,"CEF") -> 60
A18: AHUB_0001 | B18: AHU | C18: Air Handling Unit | F18: SF | G18: =COUNTIF(B:B,"SF") -> 16
A19: AHUB_0002 | B19: AHU | C19: Air Handling Unit | F19: Generator | G19: =COUNTIF(B:B,"Generator") -> 2
A20: AHUB_0003 | B20: AHU | C20: Air Handling Unit | F20: TOTAL | G20: =SUM(G7:G19) -> 912
A21: AHUB_0004 | B21: AHU | C21: Air Handling Unit
A22: AHUB_0005 | B22: AHU | C22: Air Handling Unit
A23: AHUB_0006 | B23: AHU | C23: Air Handling Unit
A24: AHUB_0007 | B24: AHU | C24: Air Handling Unit
A25: AHUB_0008 | B25: AHU | C25: Air Handling Unit
A26: AHUB_0009 | B26: AHU | C26: Air Handling Unit
A27: AHUB_0010 | B27: AHU | C27: Air Handling Unit | F27: # | G27: Equipment type | H27: Tag(s) in IO list | I27: Assumption
A28: AHUB_0011 | B28: AHU | C28: Air Handling Unit | F28: 1 | G28: AHU | H28: AHU12_0010 | I28: These two tags refer to the same physical unit
A29: DX_B0001 | B29: DX Unit | C29: DX Unit - Interior | H29: AHU12_10
A30: DX_B0002 | B30: DX Unit | C30: DX Unit - Interior | F30: 2 | G30: AHU | H30: AHUB01_02 | I30: These two tags refer to the same physical unit
A31: DX_B0003 | B31: DX Unit | C31: DX Unit - Interior | H31: AHUB_0002
A32: DX_B0004 | B32: DX Unit | C32: DX Unit - Interior | F32: 3 | G32: AHU | H32: AHUB03_04 | I32: These two tags refer to the same physical unit
A33: DX_B0005 | B33: DX Unit | C33: DX Unit - Interior | H33: AHUB_0004
A34: DX_B0006 | B34: DX Unit | C34: DX Unit - Interior | F34: 4 | G34: AHU | H34: AHUB05_06 | I34: These two tags refer to the same physical unit
A35: DX_B0007 | B35: DX Unit | C35: DX Unit - Interior | H35: AHUB_0006
A36: DX_B0008 | B36: DX Unit | C36: DX Unit - Interior | F36: 5 | G36: AHU | H36: AHUB07 | I36: These two tags refer to the same physical unit
A37: DX_B0009 | B37: DX Unit | C37: DX Unit - Interior | H37: AHUB_0007
A38: DX_B0010 | B38: DX Unit | C38: DX Unit - Interior | F38: 6 | G38: AHU | H38: AHUB08 | I38: These two tags refer to the same physical unit
A39: DX_B0011 | B39: DX Unit | C39: DX Unit - Interior | H39: AHUB_0008
A40: DX_B0012 | B40: DX Unit | C40: DX Unit - Interior | F40: 7 | G40: AHU | H40: AHUB10 | I40: These two tags refer to the same physical unit
...

Sheet QNL Asset Register
A1: EQUIPMENT ASSET REGISTER
A2: Tag No. | B2: Equipment Type | C2: Description | D2: Remarks
A3: AHUB001 | B3: AHU | C3: Air Handling Unit
A4: AHUB002 | B4: AHU | C4: Air Handling Unit
A5: AHUB003 | B5: AHU | C5: Air Handling Unit
A6: AHUB004 | B6: AHU | C6: Air Handling Unit | H6: EQUIPMENT COUNT SUMMARY
A7: AHUB005 | B7: AHU | C7: Air Handling Unit | H7: AHU | I7: =COUNTIF(B:B,"AHU") -> 15
A8: AHUB006 | B8: AHU | C8: Air Handling Unit | H8: FCU | I8: =COUNTIF(B:B,"FCU") -> 137
A9: AHUB007 | B9: AHU | C9: Air Handling Unit | H9: CHW Pump | I9: =COUNTIF(B:B,"CHW Pump") -> 6
A10: AHUB008 | B10: AHU | C10: Air Handling Unit | H10: Variable Air Volume | I10: =COUNTIF(B:B,"VAV") -> 248
A11: AHUB009 | B11: AHU | C11: Air Handling Unit | H11: Constant Air Volume | I11: =COUNTIF(B:B,"CAV") -> 51
A12: AHUB010 | B12: AHU | C12: Air Handling Unit | H12: DX Unit | I12: =COUNTIF(B:B,"DX Unit") -> 24
A13: AHUB011 | B13: AHU | C13: Air Handling Unit | H13: Heat Exchanger | I13: =COUNTIF(B:B,"HEX") -> 5
A14: AHUB012 | B14: AHU | C14: Air Handling Unit | H14: CCU | I14: =COUNTIF(B:B,"CCU") -> 22
A15: AHUB013 | B15: AHU | C15: Air Handling Unit | H15: EF | I15: =COUNTIF(B:B,"EF") -> 18
A16: AHUB014 | B16: AHU | C16: Air Handling Unit | H16: SEF | I16: =COUNTIF(B:B,"SEF") -> 12
A17: AHUB015 | B17: AHU | C17: Air Handling Unit | H17: TEF | I17: =COUNTIF(B:B,"TEF") -> 8
A18: DX_B01 | B18: DX Unit | C18: DX Unit | H18: KEF | I18: =COUNTIF(B:B,"KEF") -> 4
A19: DX_B02 | B19: DX Unit | C19: DX Unit | H19: Generator | I19: =COUNTIF(B:B,"Generator") -> 1
A20: DX_B03 | B20: DX Unit | C20: DX Unit | H20: TOTAL | I20: =SUM(I7:I18) -> 550
A21: DX_B04 | B21: DX Unit | C21: DX Unit
A22: DX_B05 | B22: DX Unit | C22: DX Unit
A23: DX_B06 | B23: DX Unit | C23: DX Unit
A24: DX_B07 | B24: DX Unit | C24: DX Unit | H24: # | I24: Equipment type | J24: Tag(s) in IO list | K24: Assumption
A25: DX_B08 | B25: DX Unit | C25: DX Unit | H25: 1 | I25: EF | J25: EF_RP001 | K25: This is the same asset as : EF_RP01
A26: DX_B09 | B26: DX Unit | C26: DX Unit | H26: 2 | I26: EF | J26: EF_RP002 | K26: This is the same asset as : EF_RP02
A27: DX_B10 | B27: DX Unit | C27: DX Unit | H27: 3 | I27: EF | J27: EF_RP003 | K27: This is the same asset as : EF_RP03
A28: DX_B11 | B28: DX Unit | C28: DX Unit | H28: 4 | I28: EF | J28: EF_B009 | K28: This is the same asset as : EF_B09
A29: DX_B12 | B29: DX Unit | C29: DX Unit | H29: 5 | I29: EF | J29: EF_B011 | K29: This is the same asset as : EF_B11
A30: DX_B13 | B30: DX Unit | C30: DX Unit | H30: 6 | I30: DX Unit | J30: DX_B0010 | K30: This is the same asset as : DX_B10
A31: DX_B14 | B31: DX Unit | C31: DX Unit | H31: 7 | I31: DX Unit | J31: DX_B0011 | K31: This is the same asset as : DX_B11
A32: DX_B15 | B32: DX Unit | C32: DX Unit | H32: 8 | I32: DX Unit | J32: DX_B0012 | K32: This is the same asset as : DX_B12
A33: DX_B16 | B33: DX Unit | C33: DX Unit | H33: 9 | I33: DX Unit | J33: DX_B0020 | K33: This is the same asset as : DX_B20
A34: DX_B17 | B34: DX Unit | C34: DX Unit | H34: 10 | I34: DX Unit | J34: DX_B022 | K34: This is the same asset as : DX_B21
A35: DX_B18 | B35: DX Unit | C35: DX Unit | H35: 11 | I35: DX Unit | J35: DX_B023 | K35: This is the same asset as : DX_B22
A36: DX_B19 | B36: DX Unit | C36: DX Unit | H36: 12 | I36: DX Unit | J36: DX_B22 | K36: This DX unit was added later and not reflected in the HVAC Drawing
... A38: DX_B21 | B38: DX Unit | C38: DX Unit | H38: 14 | I38: DX Unit | J38: DX_B24 | K38: This DX unit was added later and not reflected in the HVAC Drawing
A39: DX_B22 | B39: DX Unit | C39: DX Unit | D39: This asset is available in the Local and SWS SCADA but not in the HVAC Drawings | H39: 15 | I39: HEX | J39: HEX05 | K39: This Heat Exchanger was added later and not reflecteed in the HVAC Drawing
A40: DX_B23 | B40: DX Unit | C40: DX Unit | D40: This asset is available in the Local and SWS SCADA but not in the HVAC Drawings | H40: 16 | I40: CCU | J40: CCU_AVServer_Rm | K40: This CCU is available in the Local SCADA but not configures in the SWS
A41: DX_B24 | B41: DX Unit | C41: DX Unit | D41: This asset is available in the Local and SWS SCADA but not in the HVAC Drawings
...

Sheet SSC Asset Register
A1: EQUIPMENT ASSET REGISTER
A2: Tag No. | B2: Equipment Type | C2: Description | D2: Remarks
A3: AHUB_0001 | B3: AHU | C3: Air Handling Unit
A4: AHUB_0002 | B4: AHU | C4: Air Handling Unit
A5: AHUB_0003 | B5: AHU | C5: Air Handling Unit
A6: AHUB_0004 | B6: AHU | C6: Air Handling Unit | F6: EQUIPMENT COUNT SUMMARY
A7: AHUB_0005 | B7: AHU | C7: Air Handling Unit | F7: AHU | G7: =COUNTIF(B:B,"AHU") -> 5
A8: FCU0001 | B8: FCU | C8: Fan Coil Unit | F8: FCU | G8: =COUNTIF(B:B,"FCU") -> 11
A9: FCU0002 | B9: FCU | C9: Fan Coil Unit | F9: CHW Pump | G9: =COUNTIF(B:B,"CHW Pump") -> 8
A10: FCU0003 | B10: FCU | C10: Fan Coil Unit | F10: Variable Air Volume | G10: =COUNTIF(B:B,"VAV") -> 108
A11: FCU0004 | B11: FCU | C11: Fan Coil Unit | F11: DX Unit | G11: =COUNTIF(B:B,"DX Unit") -> 10
A12: FCU0005 | B12: FCU | C12: Fan Coil Unit | F12: Heat Exchanger | G12: =COUNTIF(B:B,"HEX") -> 5
A13: FCU0006 | B13: FCU | C13: Fan Coil Unit | F13: CCU | G13: =COUNTIF(B:B,"CCU") -> 14
A14: FCU0007 | B14: FCU | C14: Fan Coil Unit | F14: EF | G14: =COUNTIF(B:B,"EF") -> 1
A15: FCU0008 | B15: FCU | C15: Fan Coil Unit | F15: KEF | G15: =COUNTIF(B:B,"KEF") -> 2
A16: FCU0009 | B16: FCU | C16: Fan Coil Unit | F16: TEF | G16: =COUNTIF(B:B,"TEF") -> 4
A17: FCU0010 | B17: FCU | C17: Fan Coil Unit | F17: GEF | G17: =COUNTIF(B:B,"GEF") -> 1
A18: FCU0011 | B18: FCU | C18: Fan Coil Unit | F18: Generator | G18: =COUNTIF(B:B,"Generator") -> 1
A19: VAV0001 | B19: VAV | C19: Variable Air Volume | F19: TOTAL | G19: =SUM(G7:G18) -> 170
A20: VAV0002 | B20: VAV | C20: Variable Air Volume
A21: VAV0003 | B21: VAV | C21: Variable Air Volume
A22: VAV0004 | B22: VAV | C22: Variable Air Volume
A23: VAV0005 | B23: VAV | C23: Variable Air Volume
A24: VAV0006 | B24: VAV | C24: Variable Air Volume
A25: VAV0007 | B25: VAV | C25: Variable Air Volume
A26: VAV0008 | B26: VAV | C26: Variable Air Volume | F26: # | G26: Equipment type | H26: Tag(s) in IO list | I26: Assumption
A27: VAV0009 | B27: VAV | C27: Variable Air Volume | F27: 1 | G27: DX Unit | H27: DX/B/11 | I27: This DX unit is not available in I/O (Local and SWS) but available in the drawings
A28: VAV0010 | B28: VAV | C28: Variable Air Volume | F28: 2 | G28: DX Unit | H28: DX/B/12 | I28: This DX unit is not available in I/O (Local and SWS) but available in the drawings
A29: VAV0011 | B29: VAV | C29: Variable Air Volume | F29: 3 | G29: DX Unit | H29: DX/B/13 | I29: This DX unit is not available in I/O (Local and SWS) but available in the drawings
A30: VAV0012 | B30: VAV | C30: Variable Air Volume | F30: 4 | G30: DX Unit | H30: DX/B/14 | I30: This DX unit is not available in I/O (Local and SWS) but available in the drawings
A31: VAV0013 | B31: VAV | C31: Variable Air Volume | F31: 5 | G31: DX Unit | H31: DX/B/15 | I31: This DX unit is not available in I/O (Local and SWS) but available in the drawings
A32: VAV0014 | B32: VAV | C32: Variable Air Volume | F32: 6 | G32: DX Unit | H32: DX/B/16 | I32: This DX unit is not available in I/O (Local and SWS) but available in the drawings
A33: VAV0015 | B33: VAV | C33: Variable Air Volume | F33: 7 | G33: DX Unit | H33: DX/1/01 | I33: This DX unit is not available in I/O (Local and SWS) but available in the drawings
A34: VAV0016 | B34: VAV | C34: Variable Air Volume | F34: 8 | G34: DX Unit | H34: DX/1/02 | I34: This DX unit is not available in I/O (Local and SWS) but available in the drawings
A35: VAV0017 | B35: VAV | C35: Variable Air Volume | F35: 9 | G35: DX Unit | H35: DX/1/03 | I35: This DX unit is not available in I/O (Local and SWS) but available in the drawings
A36: VAV0018 | B36: VAV | C36: Variable Air Volume
A37: VAV0019 | B37: VAV | C37: Variable Air Volume
A38: VAV0020 | B38: VAV | C38: Variable Air Volume
A39: VAV0021 | B39: VAV | C39: Variable Air Volume
A40: VAV0022 | B40: VAV | C40: Variable Air Volume
...

Sheet RDC Asset Register
A1: EQUIPMENT ASSET REGISTER
A2: Tag No. | B2: Equipment Type | C2: Description | D2: Remarks
A3: NB_AHU8511 | B3: AHU | C3: Air Handling Unit
A4: NB_AHU8512 | B4: AHU | C4: Air Handling Unit
A5: NB_AHU8513 | B5: AHU | C5: Air Handling Unit
A6: NB_AHU8514 | B6: AHU | C6: Air Handling Unit | H6: EQUIPMENT COUNT SUMMARY
A7: NB_AHU8515 | B7: AHU | C7: Air Handling Unit | H7: AHU | I7: =COUNTIF(B:B,"AHU") -> 37
A8: NB_AHU8516 | B8: AHU | C8: Air Handling Unit | H8: ERU | I8: =COUNTIF(B:B,"ERU") -> 11
A9: NB_AHU8517 | B9: AHU | C9: Air Handling Unit | H9: FCU | I9: =COUNTIF(B:B,"FCU") -> 135
A10: NB_AHU8518 | B10: AHU | C10: Air Handling Unit | H10: CHW Pump | I10: =COUNTIF(B:B,"CHW Pump") -> 9
A11: NB_AHU8519 | B11: AHU | C11: Air Handling Unit | H11: Variable Air Volume | I11: =COUNTIF(B:B,"VAV") -> 739
A12: NB_AHU8520 | B12: AHU | C12: Air Handling Unit | H12: Constant Air Volume | I12: =COUNTIF(B:B,"CAV") -> 78
A13: NB_AHU8521 | B13: AHU | C13: Air Handling Unit | H13: FEV | I13: =COUNTIF(B:B,"FEV") -> 76
A14: RDC_NB_ERU8531 | B14: ERU | C14: ERU | H14: VEV | I14: =COUNTIF(B:B,"VEV") -> 44
A15: RDC_NB_ERU8532 | B15: ERU | C15: ERU | H15: EAV | I15: =COUNTIF(B:B,"EAV") -> 51
A16: RDC_NB_ERU8533 | B16: ERU | C16: ERU | H16: Heat Exchanger | I16: =COUNTIF(B:B,"HEX") -> 7
A17: RDC_NB_ERU8534 | B17: ERU | C17: ERU | H17: EF | I17: =COUNTIF(B:B,"EF") -> 38
A18: RDC_NB_ERU8535 | B18: ERU | C18: ERU | H18: Generator | I18: =COUNTIF(B:B,"Generator") -> 3
A19: RDC_NB_ERU8536 | B19: ERU | C19: ERU | H19: TOTAL | I19: =SUM(I7:I18) -> 1228
A20: RDC_NB_ERU8537 | B20: ERU | C20: ERU
A21: RDC_NB_ERU8538 | B21: ERU | C21: ERU
A22: RDC_NB_ERU8539 | B22: ERU | C22: ERU
A23: RDC_NB_ERU8540 | B23: ERU | C23: ERU
A24: RDC_NB_ERU8541 | B24: ERU | C24: ERU
A25: RDC_SB_AHU8011 | B25: AHU | C25: Air Handling Unit
A26: RDC_SB_AHU8012 | B26: AHU | C26: Air Handling Unit
A27: RDC_SB_AHU8021 | B27: AHU | C27: Air Handling Unit
A28: RDC_SB_AHU8022 | B28: AHU | C28: Air Handling Unit
A29: RDC_SB_AHU8023 | B29: AHU | C29: Air Handling Unit | H29: # | I29: Equipment type | J29: Tag(s) in IO list | K29: Assumption
A30: RDC_SB_AHU8024 | B30: AHU | C30: Air Handling Unit | H30: 1 | I30: DX Unit | J30: RDC_UB_AHU8603_DXUnit | K30: This is the DX coil/compressor of AHU8603
A31: RDC_SB_AHU8025 | B31: AHU | C31: Air Handling Unit | H31: 2 | I31: DX Unit | J31: RDC_UB_AHU8604_DXUnit | K31: This is the DX coil/compressor of AHU8604
A32: RDC_SB_AHU8026 | B32: AHU | C32: Air Handling Unit | H32: 3 | I32: DX Unit | J32: RDC_UB_AHU8605_DXUnit | K32: This is the DX coil/compressor of AHU8605
A33: RDC_SB_AHU8031 | B33: AHU | C33: Air Handling Unit | H33: 4 | I33: DX Unit | J33: RDC_UB_AHU8606_DXUnit | K33: This is the DX coil/compressor of AHU8606
A34: RDC_SB_AHU8032 | B34: AHU | C34: Air Handling Unit | H34: 5 | I34: DX Unit | J34: RDC_UB_AHU8607_DXUnit | K34: This is the DX coil/compressor of AHU8607
A35: RDC_SB_AHU8033 | B35: AHU | C35: Air Handling Unit | H35: 6 | I35: DX Unit | J35: RDC_UB_AHU8608_DXUnit | K35: This is the DX coil/compressor of AHU8608
A36: RDC_SB_AHU8034 | B36: AHU | C36: Air Handling Unit | H36: 7 | I36: DX Unit | J36: RDC_UB_AHU8609_DXUnit | K36: This is the DX coil/compressor of AHU8609
A37: RDC_SB_AHU8035 | B37: AHU | C37: Air Handling Unit | H37: 8 | I37: EF | J37: RDC_SB_BUS_EFA1 | K37: Extract fans serving the bus station
A38: RDC_SB_AHU8036 | B38: AHU | C38: Air Handling Unit | H38: 9 | I38: EF | J38: RDC_SB_BUS_EFA2 | K38: Extract fans serving the bus station
A39: RDC_SB_AHU8037 | B39: AHU | C39: Air Handling Unit | H39: 10 | I39: EF | J39: RDC_SB_BUS_EFA3 | K39: Extract fans serving the bus station
A40: RDC_SB_AHU8041 | B40: AHU | C40: Air Handling Unit | H40: 11 | I40: EF | J40: RDC_SB_BUS_EFA4 | K40: Extract fans serving the bus station
...

Sheet Controllable Asset Registry
A1: Controllable Asset Registry
A2: Tag No. | B2: Equipment Type | C2: Inluded/ Not Inlcuded | D2: ROOM NAME AS PER DRAWINGS | H2: ROOM NAME PER VAV / FCU LIST (WHERE DIFFERENT) | J2: ROOM PER BMS SCREEN | K2: BMS SCREEN (IMAGE FILE)
A3: QNL
A4: AHUB001 | B4: AHU | C4: Not Included | D4: Basement Level Zone 4 Plant Room 4 B.220 | E4: entity:QNL_B_220_PLANT_ROOM_04
A5: AHUB002 | B5: AHU | C5: Not Included | D5: Basement Level Zone 1 Plant Room 1 B.063 | E5: entity:QNL_B_063_PLANT_ROOM_01
A6: AHUB003 | B6: AHU | C6: Not Included | D6: Basement Level Zone 1 Plant Room 2 B.070 | E6: entity:QNL_B_070_PLANT_ROOM_02
A7: AHUB004 | B7: AHU | C7: Not Included | D7: Basement Level Zone 2 Plant Room 3 B.110 | E7: entity:QNL_B_110_PLANT_ROOM_03
A8: AHUB005 | B8: AHU | C8: Not Included | D8: Basement Level Zone 4 Plant Room 4 B.220 | E8: entity:QNL_B_220_PLANT_ROOM_04
A9: AHUB006 | B9: AHU | C9: Not Included | D9: Basement Level Zone 4 Plant Room 4 B.220 | E9: entity:QNL_B_220_PLANT_ROOM_04
A10: AHUB007 | B10: AHU | C10: Not Included | D10: Basement Level Zone 4 Plant Room 4 B.220 | E10: entity:QNL_B_220_PLANT_ROOM_04
A11: AHUB008 | B11: AHU | C11: Not Included | D11: Basement Level Zone 4 Plant Room 4 B.220 | E11: entity:QNL_B_220_PLANT_ROOM_04
A12: AHUB009 | B12: AHU | C12: Not Included | D12: Basement Level Zone 2 Plant Room 3 B.110 | E12: entity:QNL_B_110_PLANT_ROOM_03
A13: AHUB010 | B13: AHU | C13: Not Included | D13: Basement Level Zone 1 Plant Room 2 B.070 | E13: entity:QNL_B_070_PLANT_ROOM_02
A14: AHUB011 | B14: AHU | C14: Not Included | D14: Basement Level Zone 1 Plant Room 1 B.063 | E14: entity:QNL_B_063_PLANT_ROOM_01
A15: AHUB012 | B15: AHU | C15: Not Included | D15: Basement Level Zone 1 Plant Room 1 B.063 | E15: entity:QNL_B_063_PLANT_ROOM_01
... A20: FCU_1F_002 | B20: FCU | C20: Included | D20: ICT Room 02 L1.030 | E20: entity:QNL_L1_030_ICT_ROOM_02
A21: FCU_1F_003 | B21: FCU | C21: Not Included | D21: IDF Room 02 L1.099 | E21: entity:QNL_L1_099_IDF_ROOM_02 | J21: IDF Rm | K21: QNL/FF-2.jpg
A22: FCU_1F_004 | B22: FCU | C22: Included | D22: BRIDGE CEILING VOID L1.BR6 | E22: entity:QNL_L1_BR6_BRIDGE_CEILING_VOID
A23: FCU_1F_005 | B23: FCU | C23: Included | D23: BRIDGE CEILING VOID L1.BR6 | E23: entity:QNL_L1_BR6_BRIDGE_CEILING_VOID
A24: FCU_1F_006 | B24: FCU | C24: Included | D24: BRIDGE CEILING VOID L1.BR6 | E24: entity:QNL_L1_BR6_BRIDGE_CEILING_VOID
A25: FCU_1F_007 | B25: FCU | C25: Included | D25: BRIDGE CEILING VOID L1.BR6 | E25: entity:QNL_L1_BR6_BRIDGE_CEILING_VOID
A26: FCU_1F_008 | B26: FCU | C26: Included | D26: BRIDGE CEILING VOID L1.BR6 | E26: entity:QNL_L1_BR6_BRIDGE_CEILING_VOID
A27: FCU_1F_009 | B27: FCU | C27: Included | D27: BRIDGE CEILING VOID L1.BR5 | E27: entity:QNL_L1_BR5_BRIDGE_CEILING_VOID
A28: FCU_1F_010 | B28: FCU | C28: Included | D28: BRIDGE CEILING VOID L1.BR5 | E28: entity:QNL_L1_BR5_BRIDGE_CEILING_VOID
A29: FCU_1F_011 | B29: FCU | C29: Included | D29: BRIDGE CEILING VOID L1.BR5 | E29: entity:QNL_L1_BR5_BRIDGE_CEILING_VOID
A30: FCU_1F_012 | B30: FCU | C30: Included | D30: BRIDGE CEILING VOID L1.BR5 | E30: entity:QNL_L1_BR5_BRIDGE_CEILING_VOID
A31: FCU_1F_013 | B31: FCU | C31: Included | D31: BRIDGE CEILING VOID L1.BR6 | E31: entity:QNL_L1_BR6_BRIDGE_CEILING_VOID
A32: FCU_1F_014 | B32: FCU | C32: Included | D32: BRIDGE CEILING VOID L1.BR4 | E32: entity:QNL_L1_BR4_BRIDGE_CEILING_VOID
A33: FCU_1F_015 | B33: FCU | C33: Included | D33: BRIDGE CEILING VOID L1.BR6 | E33: entity:QNL_L1_BR6_BRIDGE_CEILING_VOID
... A77: FCU_1F_059 | B77: FCU | C77: Included | D77: Restaurant L1.150 | E77: entity:QNL_L1_150_RESTAURANT
A78: FCU_1F_060 | B78: FCU | C78: Included | D78: Restaurant L1.150 | E78: entity:QNL_L1_150_RESTAURANT | J78: Restaurant | K78: QNL/FF-2.jpg
A79: FCU_1F_061 | B79: FCU | C79: Included | D79: Restaurant L1.150 | E79: entity:QNL_L1_150_RESTAURANT | J79: Restaurant | K79: QNL/FF-2.jpg
A80: FCU_1F_062 | B80: FCU | C80: Included | D80: Restaurant L1.150 | E80: entity:QNL_L1_150_RESTAURANT
A81: FCU_1F_063 | B81: FCU | C81: Included | D81: Restaurant L1.150 | E81: entity:QNL_L1_150_RESTAURANT
A82: FCU_1F_064 | B82: FCU | C82: Included | D82: Restaurant L1.150 | E82: entity:QNL_L1_150_RESTAURANT | J82: Restaurant | K82: QNL/FF-2.jpg
A83: FCU_1F_065 | B83: FCU | C83: Not Included | D83: BRIDGE IDF L1.BI | E83: entity:QNL_L1_BI_BRIDGE_IDF
A84: FCU_2F_001 | B84: FCU | C84: Not Included | D84: IDF ROOM T1.275 | E84: entity:QNL_T1_275_IDF_ROOM
A85: FCU_2F_002 | B85: FCU | C85: Not Included | D85: IDF ROOM T1.276 | E85: entity:QNL_T1_276_IDF_ROOM
A86: FCU_2F_003 | B86: FCU | C86: Not Included | D86: IDF ROOM T1.171 | E86: entity:QNL_T1_171_IDF_ROOM
A87: FCU_2F_004 | B87: FCU | C87: Not Included | D87: IDF ROOM T1.1714 | E87: entity:QNL_T1_1714_IDF_ROOM
...

Sheet SSC Room Names with Equip.
A1: Name | B1: Number | C1: entity to use in Ontology | D1: Equipment located in Entity
A2: VENT PLANT | B2: B1.014 | C2: entity:SSC_B1_014_VENT_PLANT | D2: {=TRANSPOSE(_xlfn._xlws.FILTER('Controllable Asset Registry'!#REF!,IFERROR('Controllable Asset Registry'!#REF!=C2,FALSE),"No Equipment in entity"))} -> #REF! | E2: #REF!
A3: CHILLED WATER | B3: B1.013 | C3: entity:SSC_B1_013_CHILLED_WATER | D3: {=TRANSPOSE(_xlfn._xlws.FILTER('Controllable Asset Registry'!#REF!,IFERROR('Controllable Asset Registry'!#REF!=C3,FALSE),"No Equipment in entity"))} -> #REF! | E3: #REF!
A4: GENERATOR | B4: B1.012 | C4: entity:SSC_B1_012_GENERATOR | D4: {=TRANSPOSE(_xlfn._xlws.FILTER('Controllable Asset Registry'!#REF!,IFERROR('Controllable Asset Registry'!#REF!=C4,FALSE),"No Equipment in entity"))} -> #REF!
A5: STAIR-1 | B5: B1.ST-1 | C5: entity:SSC_B1_ST-1_STAIR-1 | D5: {=TRANSPOSE(_xlfn._xlws.FILTER('Controllable Asset Registry'!#REF!,IFERROR('Controllable Asset Registry'!#REF!=C5,FALSE),"No Equipment in entity"))} -> #REF!
A6: ENTRANCE | B6: B1.015 | C6: entity:SSC_B1_015_ENTRANCE | D6: {=TRANSPOSE(_xlfn._xlws.FILTER('Controllable Asset Registry'!#REF!,IFERROR('Controllable Asset Registry'!#REF!=C6,FALSE),"No Equipment in entity"))} -> #REF!
A7: LIFT | B7: B1.P-1 | C7: entity:SSC_B1_P-1_P1 | D7: {=TRANSPOSE(_xlfn._xlws.FILTER('Controllable Asset Registry'!#REF!,IFERROR('Controllable Asset Registry'!#REF!=C7,FALSE),"No Equipment in entity"))} -> #REF!
A8: LIFT | B8: B1.P-2 | C8: entity:SSC_B1_P-2_P2 | D8: {=TRANSPOSE(_xlfn._xlws.FILTER('Controllable Asset Registry'!#REF!,IFERROR('Controllable Asset Registry'!#REF!=C8,FALSE),"No Equipment in entity"))} -> #REF!
A9: SPRINKLER & WATER | B9: B1.016 | C9: entity:SSC_B1_016_SPRINKLER_&_WATER | D9: {=TRANSPOSE(_xlfn._xlws.FILTER('Controllable Asset Registry'!#REF!,IFERROR('Controllable Asset Registry'!#REF!=C9,FALSE),"No Equipment in entity"))} -> #REF!
A10: SER-2 | B10: B1.038 | C10: entity:SSC_B1_038_SER-2 | D10: {=TRANSPOSE(_xlfn._xlws.FILTER('Controllable Asset Registry'!#REF!,IFERROR('Controllable Asset Registry'!#REF!=C10,FALSE),"No Equipment in entity"))} -> #REF!
A11: MDF-2 | B11: B1.017 | C11: entity:SSC_B1_017_MDF-2 | D11: {=TRANSPOSE(_xlfn._xlws.FILTER('Controllable Asset Registry'!#REF!,IFERROR('Controllable Asset Registry'!#REF!=C11,FALSE),"No Equipment in entity"))} -> #REF!
A12: FM STORAGE | B12: B1.019 | C12: entity:SSC_B1_019_FM_STORAGE | D12: {=TRANSPOSE(_xlfn._xlws.FILTER('Controllable Asset Registry'!#REF!,IFERROR('Controllable Asset Registry'!#REF!=C12,FALSE),"No Equipment in entity"))} -> #REF!
A13: CONDENSER ROOM | B13: B1.018 | C13: entity:SSC_B1_018_CONDENSER_ROOM | D13: {=TRANSPOSE(_xlfn._xlws.FILTER('Controllable Asset Registry'!#REF!,IFERROR('Controllable Asset Registry'!#REF!=C13,FALSE),"No Equipment in entity"))} -> #REF!
A14: FILE STORAGE | B14: B1.028 | C14: entity:SSC_B1_028_FILE_STORAGE | D14: {=TRANSPOSE(_xlfn._xlws.FILTER('Controllable Asset Registry'!#REF!,IFERROR('Controllable Asset Registry'!#REF!=C14,FALSE),"No Equipment in entity"))} -> #REF!
A15: CORRIDOR | B15: B1.030 | C15: entity:SSC_B1_030_CORRIDOR | D15: {=TRANSPOSE(_xlfn._xlws.FILTER('Controllable Asset Registry'!#REF!,IFERROR('Controllable Asset Registry'!#REF!=C15,FALSE),"No Equipment in entity"))} -> #REF!
... A43: STAIR-9 | B43: 01.ST-9 | C43: entity:SSC_01_ST-9_STAIR-9 | D43: {=TRANSPOSE(_xlfn._xlws.FILTER('Controllable Asset Registry'!#REF!,IFERROR('Controllable Asset Registry'!#REF!=C43,FALSE),"No Equipment in entity"))} -> #REF!
A44: OUTDOOR AREA | B44: 1.037 | C44: entity:SSC_01_037_OUTDOOR_AREA | D44: {=TRANSPOSE(_xlfn._xlws.FILTER('Controllable Asset Registry'!#REF!,IFERROR('Controllable Asset Registry'!#REF!=C44,FALSE),"No Equipment in entity"))} -> #REF!
A45: SHELL SPACE | B45: 1.014 | C45: entity:SSC_01_014_SHELL_SPACE | D45: {=TRANSPOSE(_xlfn._xlws.FILTER('Controllable Asset Registry'!#REF!,IFERROR('Controllable Asset Registry'!#REF!=C45,FALSE),"No Equipment in entity"))} -> #REF! | E45: #REF! | F45: #REF!
A46: STAIR-3 | B46: 01.ST-3 | C46: entity:SSC_01_ST-3_STAIR-3 | D46: {=TRANSPOSE(_xlfn._xlws.FILTER('Controllable Asset Registry'!#REF!,IFERROR('Controllable Asset Registry'!#REF!=C46,FALSE),"No Equipment in entity"))} -> #REF!
A47: SHELL SPACE | B47: 1.015 | C47: entity:SSC_01_015_SHELL_SPACE | D47: {=TRANSPOSE(_xlfn._xlws.FILTER('Controllable Asset Registry'!#REF!,IFERROR('Controllable Asset Registry'!#REF!=C47,FALSE),"No Equipment in entity"))} -> #REF! | E47: #REF! | F47: #REF!
A48: STAIR-8 | B48: 01.ST-8 | C48: entity:SSC_01_ST-8_STAIR-8 | D48: {=TRANSPOSE(_xlfn._xlws.FILTER('Controllable Asset Registry'!#REF!,IFERROR('Controllable Asset Registry'!#REF!=C48,FALSE),"No Equipment in entity"))} -> #REF!
A49: SHELL SPACE | B49: 1.016 | C49: entity:SSC_01_016_SHELL_SPACE | D49: {=TRANSPOSE(_xlfn._xlws.FILTER('Controllable Asset Registry'!#REF!,IFERROR('Controllable Asset Registry'!#REF!=C49,FALSE),"No Equipment in entity"))} -> #REF!
A50: STORAGE | B50: 1.041 | C50: entity:SSC_01_041_STORAGE_ROOM | D50: {=TRANSPOSE(_xlfn._xlws.FILTER('Controllable Asset Registry'!#REF!,IFERROR('Controllable Asset Registry'!#REF!=C50,FALSE),"No Equipment in entity"))} -> #REF!
A51: FEMALE TOILET | B51: 1.017 | C51: entity:SSC_01_017_FEMALE_TOILET | D51: {=TRANSPOSE(_xlfn._xlws.FILTER('Controllable Asset Registry'!#REF!,IFERROR('Controllable Asset Registry'!#REF!=C51,FALSE),"No Equipment in entity"))} -> #REF!
A52: CORRIDOR | B52: 1.018 | C52: entity:SSC_01_018_CORRIDOR | D52: {=TRANSPOSE(_xlfn._xlws.FILTER('Controllable Asset Registry'!#REF!,IFERROR('Controllable Asset Registry'!#REF!=C52,FALSE),"No Equipment in entity"))} -> #REF!
A53: SHELL SPACE | B53: 1.002 | C53: entity:SSC_01_002_SHELL_SPACE | D53: {=TRANSPOSE(_xlfn._xlws.FILTER('Controllable Asset Registry'!#REF!,IFERROR('Controllable Asset Registry'!#REF!=C53,FALSE),"No Equipment in entity"))} -> #REF! | E53: #REF! | F53: #REF! | G53: #REF!
A54: ABLUTION ROOM | B54: 1.022 | C54: entity:SSC_01_022_ABLUTION_ROOM | D54: {=TRANSPOSE(_xlfn._xlws.FILTER('Controllable Asset Registry'!#REF!,IFERROR('Controllable Asset Registry'!#REF!=C54,FALSE),"No Equipment in entity"))} -> #REF!
A55: ABLUTION ROOM | B55: 1.021 | C55: entity:SSC_01_021_ABLUTION_ROOM | D55: {=TRANSPOSE(_xlfn._xlws.FILTER('Controllable Asset Registry'!#REF!,IFERROR('Controllable Asset Registry'!#REF!=C55,FALSE),"No Equipment in entity"))} -> #REF!
A56: CORRIDOR | B56: 1.023 | C56: entity:SSC_01_023_CORRIDOR | D56: {=TRANSPOSE(_xlfn._xlws.FILTER('Controllable Asset Registry'!#REF!,IFERROR('Controllable Asset Registry'!#REF!=C56,FALSE),"No Equipment in entity"))} -> #REF!
A57: CORRIDOR | B57: 1.02 | C57: entity:SSC_01_020_CORRIDOR | D57: {=TRANSPOSE(_xlfn._xlws.FILTER('Controllable Asset Registry'!#REF!,IFERROR('Controllable Asset Registry'!#REF!=C57,FALSE),"No Equipment in entity"))} -> #REF!
A58: CORRIDOR | B58: 1.024 | C58: entity:SSC_01_024_CORRIDOR | D58: {=TRANSPOSE(_xlfn._xlws.FILTER('Controllable Asset Registry'!#REF!,IFERROR('Controllable Asset Registry'!#REF!=C58,FALSE),"No Equipment in entity"))} -> #REF!
A59: IDF - 2 | B59: 1.039 | C59: entity:SSC_01_039_IDF_2 | D59: {=TRANSPOSE(_xlfn._xlws.FILTER('Controllable Asset Registry'!#REF!,IFERROR('Controllable Asset Registry'!#REF!=C59,FALSE),"No Equipment in entity"))} -> #REF! | E59: #REF!
A60: IDF - 1 | B60: 1.027 | C60: entity:SSC_01_027_IDF_1 | D60: {=TRANSPOSE(_xlfn._xlws.FILTER('Controllable Asset Registry'!#REF!,IFERROR('Controllable Asset Registry'!#REF!=C60,FALSE),"No Equipment in entity"))} -> #REF! | E60: #REF!
A61: FURNITURE STORAGE | B61: 1.026 | C61: entity:SSC_01_026_STORAGE_ROOM | D61: {=TRANSPOSE(_xlfn._xlws.FILTER('Controllable Asset Registry'!#REF!,IFERROR('Controllable Asset Registry'!#REF!=C61,FALSE),"No Equipment in entity"))} -> #REF!
A62: MALE TOILET | B62: 1.025 | C62: entity:SSC_01_025_MALE_TOILET | D62: {=TRANSPOSE(_xlfn._xlws.FILTER('Controllable Asset Registry'!#REF!,IFERROR('Controllable Asset Registry'!#REF!=C62,FALSE),"No Equipment in entity"))} -> #REF!
A63: PRAYER ROOM | B63: 1.019 | C63: entity:SSC_01_019_PRAYER_ROOM | D63: {=TRANSPOSE(_xlfn._xlws.FILTER('Controllable Asset Registry'!#REF!,IFERROR('Controllable Asset Registry'!#REF!=C63,FALSE),"No Equipment in entity"))} -> #REF! | E63: #REF! | F63: #REF! | G63: #REF! | H63: #REF! | I63: #REF!
A64: CORRIDOR | B64: 1.001 | C64: entity:SSC_01_001_CORRIDOR | D64: {=TRANSPOSE(_xlfn._xlws.FILTER('Controllable Asset Registry'!#REF!,IFERROR('Controllable Asset Registry'!#REF!=C64,FALSE),"No Equipment in entity"))} -> #REF! | E64: #REF! | F64: #REF!
A65: OPEN SPACE | B65: 1.003 | C65: entity:SSC_01_003_OPEN_SPACE | D65: {=TRANSPOSE(_xlfn._xlws.FILTER('Controllable Asset Registry'!#REF!,IFERROR('Controllable Asset Registry'!#REF!=C65,FALSE),"No Equipment in entity"))} -> #REF! | E65: #REF! | F65: #REF! | G65: #REF!
A66: SHELL SPACE | B66: 1.029 | C66: entity:SSC_01_029_ROOM_NO_42 | D66: {=TRANSPOSE(_xlfn._xlws.FILTER('Controllable Asset Registry'!#REF!,IFERROR('Controllable Asset Registry'!#REF!=C66,FALSE),"No Equipment in entity"))} -> #REF! | E66: #REF! | F66: #REF!
A67: STORAGE | B67: 1.012 | C67: entity:SSC_01_012_STORAGE | D67: {=TRANSPOSE(_xlfn._xlws.FILTER('Controllable Asset Registry'!#REF!,IFERROR('Controllable Asset Registry'!#REF!=C67,FALSE),"No Equipment in entity"))} -> #REF!
...

Sheet HQ Room Names with Equip.
A1: Room Entity Name | B1: Room Number Used | C1: Room Space (cleaned) | N1: Equipment Match Audit
A2: entity:HQ_B1.606_SECURE_STORAGE | B2: B1.606 | C2: SECURE_STORAGE | D2: {=TRANSPOSE(_xlfn._xlws.FILTER('Controllable Asset Registry'!#REF!,IFERROR('Controllable Asset Registry'!#REF!=A2,FALSE),"No Equipment in entity"))} -> #REF! | N2: Rooms listed (col A) | O2: =COUNTA(A2:A1042) -> 1040
A3: entity:HQ_B1.001_AHU_4 | B3: B1.001 | C3: AHU_4 | D3: {=TRANSPOSE(_xlfn._xlws.FILTER('Controllable Asset Registry'!#REF!,IFERROR('Controllable Asset Registry'!#REF!=A3,FALSE),"No Equipment in entity"))} -> #REF! | N3: Equipment names returned | O3: =COUNTA(D2:L1042)-COUNTIF(D2:L1042,"No Equipment in entity") -> 1040
A4: entity:HQ_B1.002_SECURITY_UPS_ROOM | B4: B1.002 | C4: SECURITY_UPS_ROOM | D4: {=TRANSPOSE(_xlfn._xlws.FILTER('Controllable Asset Registry'!#REF!,IFERROR('Controllable Asset Registry'!#REF!=A4,FALSE),"No Equipment in entity"))} -> #REF! | N4: Rooms with no equipment | O4: =COUNTIF(D2:L1042,"No Equipment in entity") -> 0
A5: entity:HQ_B1.003_CONTROL_ROOM | B5: B1.003 | C5: CONTROL_ROOM | D5: {=TRANSPOSE(_xlfn._xlws.FILTER('Controllable Asset Registry'!#REF!,IFERROR('Controllable Asset Registry'!#REF!=A5,FALSE),"No Equipment in entity"))} -> #REF! | N5: Equipment in source register | O5: =COUNTA('Controllable Asset Registry'!#REF!) -> 1
A6: entity:HQ_B1.005_MDF_1_ROOM | B6: B1.005 | C6: MDF_1_ROOM | D6: {=TRANSPOSE(_xlfn._xlws.FILTER('Controllable Asset Registry'!#REF!,IFERROR('Controllable Asset Registry'!#REF!=A6,FALSE),"No Equipment in entity"))} -> #REF! | N6: Distinct equipment returned | O6: {=SUM(--(_xlfn.UNIQUE(_xlfn.TOCOL(D2:L1042,3))<>"No Equipment in entity"))} -> #VALUE!
A7: entity:HQ_B1.006_AHU_1 | B7: B1.006 | C7: AHU_1 | D7: {=TRANSPOSE(_xlfn._xlws.FILTER('Controllable Asset Registry'!#REF!,IFERROR('Controllable Asset Registry'!#REF!=A7,FALSE),"No Equipment in entity"))} -> #REF! | N7: Duplicate room entries (col A) | O7: {=SUMPRODUCT((A2:A1042<>"")*(COUNTIF(A2:A1042,A2:A1042)>1))} -> 0
A8: entity:HQ_B1.007_COOLING_EQUIPMENT | B8: B1.007 | C8: COOLING_EQUIPMENT | D8: {=TRANSPOSE(_xlfn._xlws.FILTER('Controllable Asset Registry'!#REF!,IFERROR('Controllable Asset Registry'!#REF!=A8,FALSE),"No Equipment in entity"))} -> #REF! | N8: Duplicated equipment returns (D:L) | O8: {=SUMPRODUCT((D2:L1042<>"")*(D2:L1042<>"No Equipment in entity")*(COUNTIF(D2:L1042,D2:L1042)>1))} -> #REF!
A9: entity:HQ_B1.008_FM_STORAGE | B9: B1.008 | C9: FM_STORAGE | D9: {=TRANSPOSE(_xlfn._xlws.FILTER('Controllable Asset Registry'!#REF!,IFERROR('Controllable Asset Registry'!#REF!=A9,FALSE),"No Equipment in entity"))} -> #REF! | N9: Unplaced (in register, not on a room) | O9: =O5-O6 -> #VALUE!
A10: entity:HQ_B1.009_MV_SWITCH_ROOM | B10: B1.009 | C10: MV_SWITCH_ROOM | D10: {=TRANSPOSE(_xlfn._xlws.FILTER('Controllable Asset Registry'!#REF!,IFERROR('Controllable Asset Registry'!#REF!=A10,FALSE),"No Equipment in entity"))} -> #REF!
A11: entity:HQ_B1.010_TRANSFORMER_SUBSTATION | B11: B1.010 | C11: TRANSFORMER_SUBSTATION | D11: {=TRANSPOSE(_xlfn._xlws.FILTER('Controllable Asset Registry'!#REF!,IFERROR('Controllable Asset Registry'!#REF!=A11,FALSE),"No Equipment in entity"))} -> #REF!
A12: entity:HQ_B1.011_HV_INTAKE | B12: B1.011 | C12: HV_INTAKE | D12: {=TRANSPOSE(_xlfn._xlws.FILTER('Controllable Asset Registry'!#REF!,IFERROR('Controllable Asset Registry'!#REF!=A12,FALSE),"No Equipment in entity"))} -> #REF!
A13: entity:HQ_B1.012_GENERATOR | B13: B1.012 | C13: GENERATOR | D13: {=TRANSPOSE(_xlfn._xlws.FILTER('Controllable Asset Registry'!#REF!,IFERROR('Controllable Asset Registry'!#REF!=A13,FALSE),"No Equipment in entity"))} -> #REF!
A14: entity:HQ_B1.013_Q-TEL_INCOMING | B14: B1.013 | C14: Q-TEL_INCOMING | D14: {=TRANSPOSE(_xlfn._xlws.FILTER('Controllable Asset Registry'!#REF!,IFERROR('Controllable Asset Registry'!#REF!=A14,FALSE),"No Equipment in entity"))} -> #REF!
A15: entity:HQ_B1.014_SUPPORT_SPACE_DRY_WASTE_STORAGE | B15: B1.014 | C15: SUPPORT_SPACE_DRY_WASTE_STORAGE | D15: {=TRANSPOSE(_xlfn._xlws.FILTER('Controllable Asset Registry'!#REF!,IFERROR('Controllable Asset Registry'!#REF!=A15,FALSE),"No Equipment in entity"))} -> #REF!
A16: entity:HQ_B1.015_SUPPORT_SPACE_LOADING | B16: B1.015 | C16: SUPPORT_SPACE_LOADING | D16: {=TRANSPOSE(_xlfn._xlws.FILTER('Controllable Asset Registry'!#REF!,IFERROR('Controllable Asset Registry'!#REF!=A16,FALSE),"No Equipment in entity"))} -> #REF!
A17: entity:HQ_B1.016_AHU_2 | B17: B1.016 | C17: AHU_2 | D17: {=TRANSPOSE(_xlfn._xlws.FILTER('Controllable Asset Registry'!#REF!,IFERROR('Controllable Asset Registry'!#REF!=A17,FALSE),"No Equipment in entity"))} -> #REF!
A18: entity:HQ_B1.017_WATER_SERVICES | B18: B1.017 | C18: WATER_SERVICES | D18: {=TRANSPOSE(_xlfn._xlws.FILTER('Controllable Asset Registry'!#REF!,IFERROR('Controllable Asset Registry'!#REF!=A18,FALSE),"No Equipment in entity"))} -> #REF!
A19: entity:HQ_B1.018_PA_ROOM | B19: B1.018 | C19: PA_ROOM | D19: {=TRANSPOSE(_xlfn._xlws.FILTER('Controllable Asset Registry'!#REF!,IFERROR('Controllable Asset Registry'!#REF!=A19,FALSE),"No Equipment in entity"))} -> #REF!
A20: entity:HQ_B1.019_AHU | B20: B1.019 | C20: AHU | D20: {=TRANSPOSE(_xlfn._xlws.FILTER('Controllable Asset Registry'!#REF!,IFERROR('Controllable Asset Registry'!#REF!=A20,FALSE),"No Equipment in entity"))} -> #REF!
A21: entity:HQ_B1.020_CHILLED_WATER | B21: B1.020 | C21: CHILLED_WATER | D21: {=TRANSPOSE(_xlfn._xlws.FILTER('Controllable Asset Registry'!#REF!,IFERROR('Controllable Asset Registry'!#REF!=A21,FALSE),"No Equipment in entity"))} -> #REF!
... A986: entity:HQ_2.701_TERRACE | B986: 2.701 | C986: TERRACE | D986: {=TRANSPOSE(_xlfn._xlws.FILTER('Controllable Asset Registry'!#REF!,IFERROR('Controllable Asset Registry'!#REF!=A986,FALSE),"No Equipment in entity"))} -> #REF!
A987: entity:HQ_5.214_GSM_ROOM | B987: 5.214 | C987: GSM_ROOM | D987: {=TRANSPOSE(_xlfn._xlws.FILTER('Controllable Asset Registry'!#REF!,IFERROR('Controllable Asset Registry'!#REF!=A987,FALSE),"No Equipment in entity"))} -> #REF!
A988: entity:HQ_4.11_PRINT_COPY | B988: 4.11 | C988: PRINT_COPY | D988: {=TRANSPOSE(_xlfn._xlws.FILTER('Controllable Asset Registry'!#REF!,IFERROR('Controllable Asset Registry'!#REF!=A988,FALSE),"No Equipment in entity"))} -> #REF!
A989: entity:HQ_12.002_MCC_CLOSET | B989: 12.002 | C989: MCC_CLOSET | D989: {=TRANSPOSE(_xlfn._xlws.FILTER('Controllable Asset Registry'!#REF!,IFERROR('Controllable Asset Registry'!#REF!=A989,FALSE),"No Equipment in entity"))} -> #REF!
A990: entity:HQ_12.003_MCC_CLOSET | B990: 12.003 | C990: MCC_CLOSET | D990: {=TRANSPOSE(_xlfn._xlws.FILTER('Controllable Asset Registry'!#REF!,IFERROR('Controllable Asset Registry'!#REF!=A990,FALSE),"No Equipment in entity"))} -> #REF!
A991: entity:HQ_12.004_MCC_CLOSET | B991: 12.004 | C991: MCC_CLOSET | D991: {=TRANSPOSE(_xlfn._xlws.FILTER('Controllable Asset Registry'!#REF!,IFERROR('Controllable Asset Registry'!#REF!=A991,FALSE),"No Equipment in entity"))} -> #REF!
A992: entity:HQ_B1.004_STAFF_ENTRANCE | B992: B1.004 | C992: STAFF_ENTRANCE | D992: {=TRANSPOSE(_xlfn._xlws.FILTER('Controllable Asset Registry'!#REF!,IFERROR('Controllable Asset Registry'!#REF!=A992,FALSE),"No Equipment in entity"))} -> #REF!
A993: entity:HQ_G.400_CORRIDOR | B993: G.400 | C993: CORRIDOR | D993: {=TRANSPOSE(_xlfn._xlws.FILTER('Controllable Asset Registry'!#REF!,IFERROR('Controllable Asset Registry'!#REF!=A993,FALSE),"No Equipment in entity"))} -> #REF!
A994: entity:HQ_G.001_PR_&_MARKET_STAFF | B994: G.001 | C994: PR_&_MARKET_STAFF | D994: {=TRANSPOSE(_xlfn._xlws.FILTER('Controllable Asset Registry'!#REF!,IFERROR('Controllable Asset Registry'!#REF!=A994,FALSE),"No Equipment in entity"))} -> #REF!
A995: entity:HQ_G.030_STAFF | B995: G.030 | C995: STAFF | D995: {=TRANSPOSE(_xlfn._xlws.FILTER('Controllable Asset Registry'!#REF!,IFERROR('Controllable Asset Registry'!#REF!=A995,FALSE),"No Equipment in entity"))} -> #REF!
A996: entity:HQ_G.602_CORRIDOR_(SOUTH_EAST) | B996: G.602 | C996: CORRIDOR_(SOUTH_EAST) | D996: {=TRANSPOSE(_xlfn._xlws.FILTER('Controllable Asset Registry'!#REF!,IFERROR('Controllable Asset Registry'!#REF!=A996,FALSE),"No Equipment in entity"))} -> #REF!
A997: entity:HQ_G.603_CORRIDOR_(SOUTH_EAST) | B997: G.603 | C997: CORRIDOR_(SOUTH_EAST) | D997: {=TRANSPOSE(_xlfn._xlws.FILTER('Controllable Asset Registry'!#REF!,IFERROR('Controllable Asset Registry'!#REF!=A997,FALSE),"No Equipment in entity"))} -> #REF!
A998: entity:HQ_1.029_FINANCE_MANAGER | B998: 1.029 | C998: FINANCE_MANAGER | D998: {=TRANSPOSE(_xlfn._xlws.FILTER('Controllable Asset Registry'!#REF!,IFERROR('Controllable Asset Registry'!#REF!=A998,FALSE),"No Equipment in entity"))} -> #REF!
A999: entity:HQ_1.401_GROUND_FLOOR_VIP_ENTRANCE | B999: 1.401 | C999: GROUND_FLOOR_VIP_ENTRANCE | D999: {=TRANSPOSE(_xlfn._xlws.FILTER('Controllable Asset Registry'!#REF!,IFERROR('Controllable Asset Registry'!#REF!=A999,FALSE),"No Equipment in entity"))} -> #REF!
A1000: entity:HQ_2.110A_OFFICE_SPACE | B1000: 2.110A | C1000: OFFICE_SPACE | D1000: {=TRANSPOSE(_xlfn._xlws.FILTER('Controllable Asset Registry'!#REF!,IFERROR('Controllable Asset Registry'!#REF!=A1000,FALSE),"No Equipment in entity"))} -> #REF!
... A1006: entity:HQ_3.202B_OFFICE_SPACE | B1006: 3.202B | C1006: OFFICE_SPACE | D1006: {=TRANSPOSE(_xlfn._xlws.FILTER('Controllable Asset Registry'!#REF!,IFERROR('Controllable Asset Registry'!#REF!=A1006,FALSE),"No Equipment in entity"))} -> #REF!
A1007: entity:HQ_4.004_STR_PL_DIR_ENSUIT | B1007: 4.004 | C1007: STR_PL_DIR_ENSUIT | D1007: {=TRANSPOSE(_xlfn._xlws.FILTER('Controllable Asset Registry'!#REF!,IFERROR('Controllable Asset Registry'!#REF!=A1007,FALSE),"No Equipment in entity"))} -> #REF!
A1008: entity:HQ_4.015C_OFFICE_SPACE | B1008: 4.015C | C1008: OFFICE_SPACE | D1008: {=TRANSPOSE(_xlfn._xlws.FILTER('Controllable Asset Registry'!#REF!,IFERROR('Controllable Asset Registry'!#REF!=A1008,FALSE),"No Equipment in entity"))} -> #REF!
A1009: entity:HQ_4.015A_OFFICE_SPACE | B1009: 4.015A | C1009: OFFICE_SPACE | D1009: {=TRANSPOSE(_xlfn._xlws.FILTER('Controllable Asset Registry'!#REF!,IFERROR('Controllable Asset Registry'!#REF!=A1009,FALSE),"No Equipment in entity"))} -> #REF!
...

Sheet QNL Room Names with Equip.
A1: Room Entity Name | B1: Room Number | C1: Room Name
A2: ="entity:QNL_"&B2&"_"&C2 -> entity:QNL_B_228_M1_HVAC_SHAFT | B2: B_228 | C2: M1_HVAC_SHAFT | D2: {=TRANSPOSE(_xlfn._xlws.FILTER('Controllable Asset Registry'!$A$4:$A$554,IFERROR('Controllable Asset Registry'!$E$4:$E$554=A2,FALSE),"No Equipment in entity"))} -> No Equipment in entity
A3: ="entity:QNL_"&B3&"_"&C3 -> entity:QNL_B_229_E1_ELEC_SHAFT | B3: B_229 | C3: E1_ELEC_SHAFT | D3: {=TRANSPOSE(_xlfn._xlws.FILTER('Controllable Asset Registry'!$A$4:$A$554,IFERROR('Controllable Asset Registry'!$E$4:$E$554=A3,FALSE),"No Equipment in entity"))} -> No Equipment in entity
